+ export 'FFLAGS=-pipe -frecord-gcc-switches -Wall -g -O2 -flto=auto'
+ FFLAGS='-pipe -frecord-gcc-switches -Wall -g -O2 -flto=auto'
+ export NO_INTERNET=YES
+ NO_INTERNET=YES
+ /usr/bin/python3 -m pyproject_installer run -- xvfb-run -- pytest -vra
INFO     : Creating venv
INFO     : Installing console scripts
INFO     : Installing package: /usr/src/RPM/BUILD/python3-module-spyder-kernels-2.5.2/dist/spyder_kernels-2.5.2-py2.py3-none-any.whl
INFO     : Running command: ['/usr/src/RPM/BUILD/python3-module-spyder-kernels-2.5.2/.run_venv/bin/python3', '-m', 'pyproject_installer', 'install', '/usr/src/RPM/BUILD/python3-module-spyder-kernels-2.5.2/dist/spyder_kernels-2.5.2-py2.py3-none-any.whl']
INFO     : Running command: ['xvfb-run', '--', 'pytest', '-vra']
_XSERVTransmkdir: ERROR: euid != 0,directory /tmp/.X11-unix will not be created.
============================= test session starts ==============================
platform linux -- Python 3.12.10, pytest-8.3.5, pluggy-1.5.0 -- /usr/src/RPM/BUILD/python3-module-spyder-kernels-2.5.2/.run_venv/bin/python3
cachedir: .pytest_cache
hypothesis profile 'default' -> database=DirectoryBasedExampleDatabase(PosixPath('/usr/src/RPM/BUILD/python3-module-spyder-kernels-2.5.2/.hypothesis/examples'))
rootdir: /usr/src/RPM/BUILD/python3-module-spyder-kernels-2.5.2
plugins: flaky-3.8.1, hypothesis-6.131.16
collecting ... collected 98 items

spyder_kernels/console/tests/test_console_kernel.py::test_magics PASSED  [  1%]
spyder_kernels/console/tests/test_console_kernel.py::test_get_namespace_view PASSED [  2%]
spyder_kernels/console/tests/test_console_kernel.py::test_comprehensions_with_locals_in_pdb PASSED [ 29%]
spyder_kernels/console/tests/test_console_kernel.py::test_comprehensions_with_locals_in_pdb_2 PASSED [ 30%]
spyder_kernels/console/tests/test_console_kernel.py::test_namespaces_in_pdb PASSED [ 31%]
spyder_kernels/console/tests/test_console_kernel.py::test_functions_with_locals_in_pdb PASSED [ 32%]
spyder_kernels/console/tests/test_console_kernel.py::test_functions_with_locals_in_pdb_2 PASSED [ 33%]
spyder_kernels/console/tests/test_console_kernel.py::test_locals_globals_in_pdb PASSED [ 34%]
spyder_kernels/console/tests/test_console_kernel.py::test_get_interactive_backend[None] SKIPPED [ 35%]
spyder_kernels/console/tests/test_console_kernel.py::test_get_interactive_backend[inline] SKIPPED [ 36%]
spyder_kernels/console/tests/test_console_kernel.py::test_get_interactive_backend[tk] SKIPPED [ 37%]
spyder_kernels/console/tests/test_console_kernel.py::test_get_interactive_backend[qt5] SKIPPED [ 38%]
spyder_kernels/console/tests/test_console_kernel.py::test_debug_namespace FAILED [ 39%]
spyder_kernels/console/tests/test_console_kernel.py::test_non_strings_in_locals PASSED [ 40%]
spyder_kernels/console/tests/test_console_kernel.py::test_django_settings PASSED [ 41%]
spyder_kernels/customize/tests/test_umr.py::test_umr_skip_cython PASSED  [ 42%]
spyder_kernels/customize/tests/test_umr.py::test_umr_run PASSED          [ 43%]
spyder_kernels/customize/tests/test_umr.py::test_umr_previous_modules PASSED [ 44%]
spyder_kernels/customize/tests/test_umr.py::test_umr_namelist PASSED     [ 45%]
spyder_kernels/customize/tests/test_umr.py::test_umr_reload_modules PASSED [ 46%]
spyder_kernels/customize/tests/test_utils.py::test_user_sitepackages_in_pathlist PASSED [ 47%]
spyder_kernels/utils/tests/test_dochelpers.py::test_dochelpers PASSED    [ 48%]
spyder_kernels/utils/tests/test_dochelpers.py::test_no_signature PASSED  [ 50%]
-- Docs: https://docs.pytest.org/en/stable/how-to/capture-warnings.html
===Flaky Test Report===

test_cwd_in_sys_path passed 1 out of the required 1 times. Success!
test_multiprocessing passed 1 out of the required 1 times. Success!
test_multiprocessing passed 1 out of the required 1 times. Success!
test_multiprocessing_2 passed 1 out of the required 1 times. Success!
test_multiprocessing_2 passed 1 out of the required 1 times. Success!
test_runfile passed 1 out of the required 1 times. Success!
test_runfile passed 1 out of the required 1 times. Success!
test_np_threshold passed 1 out of the required 1 times. Success!
test_np_threshold passed 1 out of the required 1 times. Success!
test_turtle_launch passed 1 out of the required 1 times. Success!
test_turtle_launch passed 1 out of the required 1 times. Success!
test_turtle_launch passed 1 out of the required 1 times. Success!
test_matplotlib_inline passed 1 out of the required 1 times. Success!
test_matplotlib_inline passed 1 out of the required 1 times. Success!
test_matplotlib_inline passed 1 out of the required 1 times. Success!
test_debug_namespace failed (2 runs remaining out of 3).
test_debug_namespace failed (2 runs remaining out of 3).
test_debug_namespace failed (2 runs remaining out of 3).
	<class '_queue.Empty'>
	<class '_queue.Empty'>
	<class '_queue.Empty'>
	
	
	
	[<TracebackEntry /usr/lib/python3/site-packages/_pytest/runner.py:341>, <TracebackEntry /usr/lib/python3/site-packages/flaky/flaky_pytest_plugin.py:146>, <TracebackEntry /usr/lib/python3/site-packages/pluggy/_hooks.py:513>, <TracebackEntry /usr/lib/python3/site-packages/pluggy/_manager.py:120>, <TracebackEntry /usr/lib/python3/site-packages/pluggy/_callers.py:182>, <TracebackEntry /usr/lib/python3/site-packages/pluggy/_result.py:100>, <TracebackEntry /usr/lib/python3/site-packages/pluggy/_callers.py:167>, <TracebackEntry /usr/lib/python3/site-packages/_pytest/threadexception.py:92>, <TracebackEntry /usr/lib/python3/site-packages/_pytest/threadexception.py:68>, <TracebackEntry /usr/lib/python3/site-packages/pluggy/_callers.py:167>, <TracebackEntry /usr/lib/python3/site-packages/_pytest/unraisableexception.py:95>, <TracebackEntry /usr/lib/python3/site-packages/_pytest/unraisableexception.py:70>, <TracebackEntry /usr/lib/python3/site-packages/pluggy/_callers.py:167>, <TracebackEntry /usr/lib/python3/site-packages/_pytest/logging.py:846>, <TracebackEntry /usr/lib/python3/site-packages/_pytest/logging.py:829>, <TracebackEntry /usr/lib/python3/site-packages/pluggy/_callers.py:167>, <TracebackEntry /usr/lib/python3/site-packages/_pytest/capture.py:898>, <TracebackEntry /usr/lib/python3/site-packages/pluggy/_callers.py:167>, <TracebackEntry /usr/lib/python3/site-packages/_pytest/skipping.py:257>, <TracebackEntry /usr/lib/python3/site-packages/pluggy/_callers.py:103>, <TracebackEntry /usr/lib/python3/site-packages/_pytest/runner.py:174>, <TracebackEntry /usr/lib/python3/site-packages/_pytest/python.py:1627>, <TracebackEntry /usr/lib/python3/site-packages/pluggy/_hooks.py:513>, <TracebackEntry /usr/lib/python3/site-packages/pluggy/_manager.py:120>, <TracebackEntry /usr/lib/python3/site-packages/pluggy/_callers.py:139>, <TracebackEntry /usr/lib/python3/site-packages/pluggy/_callers.py:103>, <TracebackEntry /usr/lib/python3/site-packages/_pytest/python.py:159>, <TracebackEntry /usr/src/RPM/BUILD/python3-module-spyder-kernels-2.5.2/spyder_kernels/console/tests/test_console_kernel.py:1169>, <TracebackEntry /usr/lib/python3/site-packages/jupyter_core/utils/__init__.py:165>, <TracebackEntry /usr/lib64/python3.12/asyncio/base_events.py:691>, <TracebackEntry /usr/lib/python3/site-packages/jupyter_client/client.py:151>, <TracebackEntry /usr/lib/python3/site-packages/jupyter_client/channels.py:232>]
	[<TracebackEntry /usr/lib/python3/site-packages/_pytest/runner.py:341>, <TracebackEntry /usr/lib/python3/site-packages/flaky/flaky_pytest_plugin.py:146>, <TracebackEntry /usr/lib/python3/site-packages/pluggy/_hooks.py:513>, <TracebackEntry /usr/lib/python3/site-packages/pluggy/_manager.py:120>, <TracebackEntry /usr/lib/python3/site-packages/pluggy/_callers.py:182>, <TracebackEntry /usr/lib/python3/site-packages/pluggy/_result.py:100>, <TracebackEntry /usr/lib/python3/site-packages/pluggy/_callers.py:167>, <TracebackEntry /usr/lib/python3/site-packages/_pytest/threadexception.py:92>, <TracebackEntry /usr/lib/python3/site-packages/_pytest/threadexception.py:68>, <TracebackEntry /usr/lib/python3/site-packages/pluggy/_callers.py:167>, <TracebackEntry /usr/lib/python3/site-packages/_pytest/unraisableexception.py:95>, <TracebackEntry /usr/lib/python3/site-packages/_pytest/unraisableexception.py:70>, <TracebackEntry /usr/lib/python3/site-packages/pluggy/_callers.py:167>, <TracebackEntry /usr/lib/python3/site-packages/_pytest/logging.py:846>, <TracebackEntry /usr/lib/python3/site-packages/_pytest/logging.py:829>, <TracebackEntry /usr/lib/python3/site-packages/pluggy/_callers.py:167>, <TracebackEntry /usr/lib/python3/site-packages/_pytest/capture.py:898>, <TracebackEntry /usr/lib/python3/site-packages/pluggy/_callers.py:167>, <TracebackEntry /usr/lib/python3/site-packages/_pytest/skipping.py:257>, <TracebackEntry /usr/lib/python3/site-packages/pluggy/_callers.py:103>, <TracebackEntry /usr/lib/python3/site-packages/_pytest/runner.py:174>, <TracebackEntry /usr/lib/python3/site-packages/_pytest/python.py:1627>, <TracebackEntry /usr/lib/python3/site-packages/pluggy/_hooks.py:513>, <TracebackEntry /usr/lib/python3/site-packages/pluggy/_manager.py:120>, <TracebackEntry /usr/lib/python3/site-packages/pluggy/_callers.py:139>, <TracebackEntry /usr/lib/python3/site-packages/pluggy/_callers.py:103>, <TracebackEntry /usr/lib/python3/site-packages/_pytest/python.py:159>, <TracebackEntry /usr/src/RPM/BUILD/python3-module-spyder-kernels-2.5.2/spyder_kernels/console/tests/test_console_kernel.py:1169>, <TracebackEntry /usr/lib/python3/site-packages/jupyter_core/utils/__init__.py:165>, <TracebackEntry /usr/lib64/python3.12/asyncio/base_events.py:691>, <TracebackEntry /usr/lib/python3/site-packages/jupyter_client/client.py:151>, <TracebackEntry /usr/lib/python3/site-packages/jupyter_client/channels.py:232>]
	[<TracebackEntry /usr/lib/python3/site-packages/_pytest/runner.py:341>, <TracebackEntry /usr/lib/python3/site-packages/flaky/flaky_pytest_plugin.py:146>, <TracebackEntry /usr/lib/python3/site-packages/pluggy/_hooks.py:513>, <TracebackEntry /usr/lib/python3/site-packages/pluggy/_manager.py:120>, <TracebackEntry /usr/lib/python3/site-packages/pluggy/_callers.py:182>, <TracebackEntry /usr/lib/python3/site-packages/pluggy/_result.py:100>, <TracebackEntry /usr/lib/python3/site-packages/pluggy/_callers.py:167>, <TracebackEntry /usr/lib/python3/site-packages/_pytest/threadexception.py:92>, <TracebackEntry /usr/lib/python3/site-packages/_pytest/threadexception.py:68>, <TracebackEntry /usr/lib/python3/site-packages/pluggy/_callers.py:167>, <TracebackEntry /usr/lib/python3/site-packages/_pytest/unraisableexception.py:95>, <TracebackEntry /usr/lib/python3/site-packages/_pytest/unraisableexception.py:70>, <TracebackEntry /usr/lib/python3/site-packages/pluggy/_callers.py:167>, <TracebackEntry /usr/lib/python3/site-packages/_pytest/logging.py:846>, <TracebackEntry /usr/lib/python3/site-packages/_pytest/logging.py:829>, <TracebackEntry /usr/lib/python3/site-packages/pluggy/_callers.py:167>, <TracebackEntry /usr/lib/python3/site-packages/_pytest/capture.py:898>, <TracebackEntry /usr/lib/python3/site-packages/pluggy/_callers.py:167>, <TracebackEntry /usr/lib/python3/site-packages/_pytest/skipping.py:257>, <TracebackEntry /usr/lib/python3/site-packages/pluggy/_callers.py:103>, <TracebackEntry /usr/lib/python3/site-packages/_pytest/runner.py:174>, <TracebackEntry /usr/lib/python3/site-packages/_pytest/python.py:1627>, <TracebackEntry /usr/lib/python3/site-packages/pluggy/_hooks.py:513>, <TracebackEntry /usr/lib/python3/site-packages/pluggy/_manager.py:120>, <TracebackEntry /usr/lib/python3/site-packages/pluggy/_callers.py:139>, <TracebackEntry /usr/lib/python3/site-packages/pluggy/_callers.py:103>, <TracebackEntry /usr/lib/python3/site-packages/_pytest/python.py:159>, <TracebackEntry /usr/src/RPM/BUILD/python3-module-spyder-kernels-2.5.2/spyder_kernels/console/tests/test_console_kernel.py:1169>, <TracebackEntry /usr/lib/python3/site-packages/jupyter_core/utils/__init__.py:165>, <TracebackEntry /usr/lib64/python3.12/asyncio/base_events.py:691>, <TracebackEntry /usr/lib/python3/site-packages/jupyter_client/client.py:151>, <TracebackEntry /usr/lib/python3/site-packages/jupyter_client/channels.py:232>]
test_debug_namespace failed (1 runs remaining out of 3).
test_debug_namespace failed (1 runs remaining out of 3).
test_debug_namespace failed (1 runs remaining out of 3).
	<class '_queue.Empty'>
	<class '_queue.Empty'>
	<class '_queue.Empty'>
	
	
	
	[<TracebackEntry /usr/lib/python3/site-packages/_pytest/runner.py:341>, <TracebackEntry /usr/lib/python3/site-packages/flaky/flaky_pytest_plugin.py:146>, <TracebackEntry /usr/lib/python3/site-packages/pluggy/_hooks.py:513>, <TracebackEntry /usr/lib/python3/site-packages/pluggy/_manager.py:120>, <TracebackEntry /usr/lib/python3/site-packages/pluggy/_callers.py:182>, <TracebackEntry /usr/lib/python3/site-packages/pluggy/_result.py:100>, <TracebackEntry /usr/lib/python3/site-packages/pluggy/_callers.py:167>, <TracebackEntry /usr/lib/python3/site-packages/_pytest/threadexception.py:92>, <TracebackEntry /usr/lib/python3/site-packages/_pytest/threadexception.py:68>, <TracebackEntry /usr/lib/python3/site-packages/pluggy/_callers.py:167>, <TracebackEntry /usr/lib/python3/site-packages/_pytest/unraisableexception.py:95>, <TracebackEntry /usr/lib/python3/site-packages/_pytest/unraisableexception.py:70>, <TracebackEntry /usr/lib/python3/site-packages/pluggy/_callers.py:167>, <TracebackEntry /usr/lib/python3/site-packages/_pytest/logging.py:846>, <TracebackEntry /usr/lib/python3/site-packages/_pytest/logging.py:829>, <TracebackEntry /usr/lib/python3/site-packages/pluggy/_callers.py:167>, <TracebackEntry /usr/lib/python3/site-packages/_pytest/capture.py:898>, <TracebackEntry /usr/lib/python3/site-packages/pluggy/_callers.py:167>, <TracebackEntry /usr/lib/python3/site-packages/_pytest/skipping.py:257>, <TracebackEntry /usr/lib/python3/site-packages/pluggy/_callers.py:103>, <TracebackEntry /usr/lib/python3/site-packages/_pytest/runner.py:174>, <TracebackEntry /usr/lib/python3/site-packages/_pytest/python.py:1627>, <TracebackEntry /usr/lib/python3/site-packages/pluggy/_hooks.py:513>, <TracebackEntry /usr/lib/python3/site-packages/pluggy/_manager.py:120>, <TracebackEntry /usr/lib/python3/site-packages/pluggy/_callers.py:139>, <TracebackEntry /usr/lib/python3/site-packages/pluggy/_callers.py:103>, <TracebackEntry /usr/lib/python3/site-packages/_pytest/python.py:159>, <TracebackEntry /usr/src/RPM/BUILD/python3-module-spyder-kernels-2.5.2/spyder_kernels/console/tests/test_console_kernel.py:1169>, <TracebackEntry /usr/lib/python3/site-packages/jupyter_core/utils/__init__.py:165>, <TracebackEntry /usr/lib64/python3.12/asyncio/base_events.py:691>, <TracebackEntry /usr/lib/python3/site-packages/jupyter_client/client.py:151>, <TracebackEntry /usr/lib/python3/site-packages/jupyter_client/channels.py:232>]
	[<TracebackEntry /usr/lib/python3/site-packages/_pytest/runner.py:341>, <TracebackEntry /usr/lib/python3/site-packages/flaky/flaky_pytest_plugin.py:146>, <TracebackEntry /usr/lib/python3/site-packages/pluggy/_hooks.py:513>, <TracebackEntry /usr/lib/python3/site-packages/pluggy/_manager.py:120>, <TracebackEntry /usr/lib/python3/site-packages/pluggy/_callers.py:182>, <TracebackEntry /usr/lib/python3/site-packages/pluggy/_result.py:100>, <TracebackEntry /usr/lib/python3/site-packages/pluggy/_callers.py:167>, <TracebackEntry /usr/lib/python3/site-packages/_pytest/threadexception.py:92>, <TracebackEntry /usr/lib/python3/site-packages/_pytest/threadexception.py:68>, <TracebackEntry /usr/lib/python3/site-packages/pluggy/_callers.py:167>, <TracebackEntry /usr/lib/python3/site-packages/_pytest/unraisableexception.py:95>, <TracebackEntry /usr/lib/python3/site-packages/_pytest/unraisableexception.py:70>, <TracebackEntry /usr/lib/python3/site-packages/pluggy/_callers.py:167>, <TracebackEntry /usr/lib/python3/site-packages/_pytest/logging.py:846>, <TracebackEntry /usr/lib/python3/site-packages/_pytest/logging.py:829>, <TracebackEntry /usr/lib/python3/site-packages/pluggy/_callers.py:167>, <TracebackEntry /usr/lib/python3/site-packages/_pytest/capture.py:898>, <TracebackEntry /usr/lib/python3/site-packages/pluggy/_callers.py:167>, <TracebackEntry /usr/lib/python3/site-packages/_pytest/skipping.py:257>, <TracebackEntry /usr/lib/python3/site-packages/pluggy/_callers.py:103>, <TracebackEntry /usr/lib/python3/site-packages/_pytest/runner.py:174>, <TracebackEntry /usr/lib/python3/site-packages/_pytest/python.py:1627>, <TracebackEntry /usr/lib/python3/site-packages/pluggy/_hooks.py:513>, <TracebackEntry /usr/lib/python3/site-packages/pluggy/_manager.py:120>, <TracebackEntry /usr/lib/python3/site-packages/pluggy/_callers.py:139>, <TracebackEntry /usr/lib/python3/site-packages/pluggy/_callers.py:103>, <TracebackEntry /usr/lib/python3/site-packages/_pytest/python.py:159>, <TracebackEntry /usr/src/RPM/BUILD/python3-module-spyder-kernels-2.5.2/spyder_kernels/console/tests/test_console_kernel.py:1169>, <TracebackEntry /usr/lib/python3/site-packages/jupyter_core/utils/__init__.py:165>, <TracebackEntry /usr/lib64/python3.12/asyncio/base_events.py:691>, <TracebackEntry /usr/lib/python3/site-packages/jupyter_client/client.py:151>, <TracebackEntry /usr/lib/python3/site-packages/jupyter_client/channels.py:232>]
	[<TracebackEntry /usr/lib/python3/site-packages/_pytest/runner.py:341>, <TracebackEntry /usr/lib/python3/site-packages/flaky/flaky_pytest_plugin.py:146>, <TracebackEntry /usr/lib/python3/site-packages/pluggy/_hooks.py:513>, <TracebackEntry /usr/lib/python3/site-packages/pluggy/_manager.py:120>, <TracebackEntry /usr/lib/python3/site-packages/pluggy/_callers.py:182>, <TracebackEntry /usr/lib/python3/site-packages/pluggy/_result.py:100>, <TracebackEntry /usr/lib/python3/site-packages/pluggy/_callers.py:167>, <TracebackEntry /usr/lib/python3/site-packages/_pytest/threadexception.py:92>, <TracebackEntry /usr/lib/python3/site-packages/_pytest/threadexception.py:68>, <TracebackEntry /usr/lib/python3/site-packages/pluggy/_callers.py:167>, <TracebackEntry /usr/lib/python3/site-packages/_pytest/unraisableexception.py:95>, <TracebackEntry /usr/lib/python3/site-packages/_pytest/unraisableexception.py:70>, <TracebackEntry /usr/lib/python3/site-packages/pluggy/_callers.py:167>, <TracebackEntry /usr/lib/python3/site-packages/_pytest/logging.py:846>, <TracebackEntry /usr/lib/python3/site-packages/_pytest/logging.py:829>, <TracebackEntry /usr/lib/python3/site-packages/pluggy/_callers.py:167>, <TracebackEntry /usr/lib/python3/site-packages/_pytest/capture.py:898>, <TracebackEntry /usr/lib/python3/site-packages/pluggy/_callers.py:167>, <TracebackEntry /usr/lib/python3/site-packages/_pytest/skipping.py:257>, <TracebackEntry /usr/lib/python3/site-packages/pluggy/_callers.py:103>, <TracebackEntry /usr/lib/python3/site-packages/_pytest/runner.py:174>, <TracebackEntry /usr/lib/python3/site-packages/_pytest/python.py:1627>, <TracebackEntry /usr/lib/python3/site-packages/pluggy/_hooks.py:513>, <TracebackEntry /usr/lib/python3/site-packages/pluggy/_manager.py:120>, <TracebackEntry /usr/lib/python3/site-packages/pluggy/_callers.py:139>, <TracebackEntry /usr/lib/python3/site-packages/pluggy/_callers.py:103>, <TracebackEntry /usr/lib/python3/site-packages/_pytest/python.py:159>, <TracebackEntry /usr/src/RPM/BUILD/python3-module-spyder-kernels-2.5.2/spyder_kernels/console/tests/test_console_kernel.py:1169>, <TracebackEntry /usr/lib/python3/site-packages/jupyter_core/utils/__init__.py:165>, <TracebackEntry /usr/lib64/python3.12/asyncio/base_events.py:691>, <TracebackEntry /usr/lib/python3/site-packages/jupyter_client/client.py:151>, <TracebackEntry /usr/lib/python3/site-packages/jupyter_client/channels.py:232>]
	[<TracebackEntry /usr/lib/python3/site-packages/_pytest/runner.py:341>, <TracebackEntry /usr/lib/python3/site-packages/flaky/flaky_pytest_plugin.py:146>, <TracebackEntry /usr/lib/python3/site-packages/pluggy/_hooks.py:513>, <TracebackEntry /usr/lib/python3/site-packages/pluggy/_manager.py:120>, <TracebackEntry /usr/lib/python3/site-packages/pluggy/_callers.py:182>, <TracebackEntry /usr/lib/python3/site-packages/pluggy/_result.py:100>, <TracebackEntry /usr/lib/python3/site-packages/pluggy/_callers.py:167>, <TracebackEntry /usr/lib/python3/site-packages/_pytest/threadexception.py:92>, <TracebackEntry /usr/lib/python3/site-packages/_pytest/threadexception.py:68>, <TracebackEntry /usr/lib/python3/site-packages/pluggy/_callers.py:167>, <TracebackEntry /usr/lib/python3/site-packages/_pytest/unraisableexception.py:95>, <TracebackEntry /usr/lib/python3/site-packages/_pytest/unraisableexception.py:70>, <TracebackEntry /usr/lib/python3/site-packages/pluggy/_callers.py:167>, <TracebackEntry /usr/lib/python3/site-packages/_pytest/logging.py:846>, <TracebackEntry /usr/lib/python3/site-packages/_pytest/logging.py:829>, <TracebackEntry /usr/lib/python3/site-packages/pluggy/_callers.py:167>, <TracebackEntry /usr/lib/python3/site-packages/_pytest/capture.py:898>, <TracebackEntry /usr/lib/python3/site-packages/pluggy/_callers.py:167>, <TracebackEntry /usr/lib/python3/site-packages/_pytest/skipping.py:257>, <TracebackEntry /usr/lib/python3/site-packages/pluggy/_callers.py:103>, <TracebackEntry /usr/lib/python3/site-packages/_pytest/runner.py:174>, <TracebackEntry /usr/lib/python3/site-packages/_pytest/python.py:1627>, <TracebackEntry /usr/lib/python3/site-packages/pluggy/_hooks.py:513>, <TracebackEntry /usr/lib/python3/site-packages/pluggy/_manager.py:120>, <TracebackEntry /usr/lib/python3/site-packages/pluggy/_callers.py:139>, <TracebackEntry /usr/lib/python3/site-packages/pluggy/_callers.py:103>, <TracebackEntry /usr/lib/python3/site-packages/_pytest/python.py:159>, <TracebackEntry /usr/src/RPM/BUILD/python3-module-spyder-kernels-2.5.2/spyder_kernels/console/tests/test_console_kernel.py:1169>, <TracebackEntry /usr/lib/python3/site-packages/jupyter_core/utils/__init__.py:165>, <TracebackEntry /usr/lib64/python3.12/asyncio/base_events.py:691>, <TracebackEntry /usr/lib/python3/site-packages/jupyter_client/client.py:151>, <TracebackEntry /usr/lib/python3/site-packages/jupyter_client/channels.py:232>]
test_debug_namespace failed; it passed 0 out of the required 1 times.
test_debug_namespace failed; it passed 0 out of the required 1 times.
test_debug_namespace failed; it passed 0 out of the required 1 times.
test_debug_namespace failed; it passed 0 out of the required 1 times.
test_debug_namespace failed; it passed 0 out of the required 1 times.
	<class '_queue.Empty'>
	<class '_queue.Empty'>
	<class '_queue.Empty'>
	<class '_queue.Empty'>
	<class '_queue.Empty'>
	
	
	
	
	
	
	[<TracebackEntry /usr/lib/python3/site-packages/_pytest/runner.py:341>, <TracebackEntry /usr/lib/python3/site-packages/flaky/flaky_pytest_plugin.py:146>, <TracebackEntry /usr/lib/python3/site-packages/pluggy/_hooks.py:513>, <TracebackEntry /usr/lib/python3/site-packages/pluggy/_manager.py:120>, <TracebackEntry /usr/lib/python3/site-packages/pluggy/_callers.py:182>, <TracebackEntry /usr/lib/python3/site-packages/pluggy/_result.py:100>, <TracebackEntry /usr/lib/python3/site-packages/pluggy/_callers.py:167>, <TracebackEntry /usr/lib/python3/site-packages/_pytest/threadexception.py:92>, <TracebackEntry /usr/lib/python3/site-packages/_pytest/threadexception.py:68>, <TracebackEntry /usr/lib/python3/site-packages/pluggy/_callers.py:167>, <TracebackEntry /usr/lib/python3/site-packages/_pytest/unraisableexception.py:95>, <TracebackEntry /usr/lib/python3/site-packages/_pytest/unraisableexception.py:70>, <TracebackEntry /usr/lib/python3/site-packages/pluggy/_callers.py:167>, <TracebackEntry /usr/lib/python3/site-packages/_pytest/logging.py:846>, <TracebackEntry /usr/lib/python3/site-packages/_pytest/logging.py:829>, <TracebackEntry /usr/lib/python3/site-packages/pluggy/_callers.py:167>, <TracebackEntry /usr/lib/python3/site-packages/_pytest/capture.py:898>, <TracebackEntry /usr/lib/python3/site-packages/pluggy/_callers.py:167>, <TracebackEntry /usr/lib/python3/site-packages/_pytest/skipping.py:257>, <TracebackEntry /usr/lib/python3/site-packages/pluggy/_callers.py:103>, <TracebackEntry /usr/lib/python3/site-packages/_pytest/runner.py:174>, <TracebackEntry /usr/lib/python3/site-packages/_pytest/python.py:1627>, <TracebackEntry /usr/lib/python3/site-packages/pluggy/_hooks.py:513>, <TracebackEntry /usr/lib/python3/site-packages/pluggy/_manager.py:120>, <TracebackEntry /usr/lib/python3/site-packages/pluggy/_callers.py:139>, <TracebackEntry /usr/lib/python3/site-packages/pluggy/_callers.py:103>, <TracebackEntry /usr/lib/python3/site-packages/_pytest/python.py:159>, <TracebackEntry /usr/src/RPM/BUILD/python3-module-spyder-kernels-2.5.2/spyder_kernels/console/tests/test_console_kernel.py:1169>, <TracebackEntry /usr/lib/python3/site-packages/jupyter_core/utils/__init__.py:165>, <TracebackEntry /usr/lib64/python3.12/asyncio/base_events.py:691>, <TracebackEntry /usr/lib/python3/site-packages/jupyter_client/client.py:151>, <TracebackEntry /usr/lib/python3/site-packages/jupyter_client/channels.py:232>]
	[<TracebackEntry /usr/lib/python3/site-packages/_pytest/runner.py:341>, <TracebackEntry /usr/lib/python3/site-packages/flaky/flaky_pytest_plugin.py:146>, <TracebackEntry /usr/lib/python3/site-packages/pluggy/_hooks.py:513>, <TracebackEntry /usr/lib/python3/site-packages/pluggy/_manager.py:120>, <TracebackEntry /usr/lib/python3/site-packages/pluggy/_callers.py:182>, <TracebackEntry /usr/lib/python3/site-packages/pluggy/_result.py:100>, <TracebackEntry /usr/lib/python3/site-packages/pluggy/_callers.py:167>, <TracebackEntry /usr/lib/python3/site-packages/_pytest/threadexception.py:92>, <TracebackEntry /usr/lib/python3/site-packages/_pytest/threadexception.py:68>, <TracebackEntry /usr/lib/python3/site-packages/pluggy/_callers.py:167>, <TracebackEntry /usr/lib/python3/site-packages/_pytest/unraisableexception.py:95>, <TracebackEntry /usr/lib/python3/site-packages/_pytest/unraisableexception.py:70>, <TracebackEntry /usr/lib/python3/site-packages/pluggy/_callers.py:167>, <TracebackEntry /usr/lib/python3/site-packages/_pytest/logging.py:846>, <TracebackEntry /usr/lib/python3/site-packages/_pytest/logging.py:829>, <TracebackEntry /usr/lib/python3/site-packages/pluggy/_callers.py:167>, <TracebackEntry /usr/lib/python3/site-packages/_pytest/capture.py:898>, <TracebackEntry /usr/lib/python3/site-packages/pluggy/_callers.py:167>, <TracebackEntry /usr/lib/python3/site-packages/_pytest/skipping.py:257>, <TracebackEntry /usr/lib/python3/site-packages/pluggy/_callers.py:103>, <TracebackEntry /usr/lib/python3/site-packages/_pytest/runner.py:174>, <TracebackEntry /usr/lib/python3/site-packages/_pytest/python.py:1627>, <TracebackEntry /usr/lib/python3/site-packages/pluggy/_hooks.py:513>, <TracebackEntry /usr/lib/python3/site-packages/pluggy/_manager.py:120>, <TracebackEntry /usr/lib/python3/site-packages/pluggy/_callers.py:139>, <TracebackEntry /usr/lib/python3/site-packages/pluggy/_callers.py:103>, <TracebackEntry /usr/lib/python3/site-packages/_pytest/python.py:159>, <TracebackEntry /usr/src/RPM/BUILD/python3-module-spyder-kernels-2.5.2/spyder_kernels/console/tests/test_console_kernel.py:1169>, <TracebackEntry /usr/lib/python3/site-packages/jupyter_core/utils/__init__.py:165>, <TracebackEntry /usr/lib64/python3.12/asyncio/base_events.py:691>, <TracebackEntry /usr/lib/python3/site-packages/jupyter_client/client.py:151>, <TracebackEntry /usr/lib/python3/site-packages/jupyter_client/channels.py:232>]
	[<TracebackEntry /usr/lib/python3/site-packages/_pytest/runner.py:341>, <TracebackEntry /usr/lib/python3/site-packages/flaky/flaky_pytest_plugin.py:146>, <TracebackEntry /usr/lib/python3/site-packages/pluggy/_hooks.py:513>, <TracebackEntry /usr/lib/python3/site-packages/pluggy/_manager.py:120>, <TracebackEntry /usr/lib/python3/site-packages/pluggy/_callers.py:182>, <TracebackEntry /usr/lib/python3/site-packages/pluggy/_result.py:100>, <TracebackEntry /usr/lib/python3/site-packages/pluggy/_callers.py:167>, <TracebackEntry /usr/lib/python3/site-packages/_pytest/threadexception.py:92>, <TracebackEntry /usr/lib/python3/site-packages/_pytest/threadexception.py:68>, <TracebackEntry /usr/lib/python3/site-packages/pluggy/_callers.py:167>, <TracebackEntry /usr/lib/python3/site-packages/_pytest/unraisableexception.py:95>, <TracebackEntry /usr/lib/python3/site-packages/_pytest/unraisableexception.py:70>, <TracebackEntry /usr/lib/python3/site-packages/pluggy/_callers.py:167>, <TracebackEntry /usr/lib/python3/site-packages/_pytest/logging.py:846>, <TracebackEntry /usr/lib/python3/site-packages/_pytest/logging.py:829>, <TracebackEntry /usr/lib/python3/site-packages/pluggy/_callers.py:167>, <TracebackEntry /usr/lib/python3/site-packages/_pytest/capture.py:898>, <TracebackEntry /usr/lib/python3/site-packages/pluggy/_callers.py:167>, <TracebackEntry /usr/lib/python3/site-packages/_pytest/skipping.py:257>, <TracebackEntry /usr/lib/python3/site-packages/pluggy/_callers.py:103>, <TracebackEntry /usr/lib/python3/site-packages/_pytest/runner.py:174>, <TracebackEntry /usr/lib/python3/site-packages/_pytest/python.py:1627>, <TracebackEntry /usr/lib/python3/site-packages/pluggy/_hooks.py:513>, <TracebackEntry /usr/lib/python3/site-packages/pluggy/_manager.py:120>, <TracebackEntry /usr/lib/python3/site-packages/pluggy/_callers.py:139>, <TracebackEntry /usr/lib/python3/site-packages/pluggy/_callers.py:103>, <TracebackEntry /usr/lib/python3/site-packages/_pytest/python.py:159>, <TracebackEntry /usr/src/RPM/BUILD/python3-module-spyder-kernels-2.5.2/spyder_kernels/console/tests/test_console_kernel.py:1169>, <TracebackEntry /usr/lib/python3/site-packages/jupyter_core/utils/__init__.py:165>, <TracebackEntry /usr/lib64/python3.12/asyncio/base_events.py:691>, <TracebackEntry /usr/lib/python3/site-packages/jupyter_client/client.py:151>, <TracebackEntry /usr/lib/python3/site-packages/jupyter_client/channels.py:232>]
	[<TracebackEntry /usr/lib/python3/site-packages/_pytest/runner.py:341>, <TracebackEntry /usr/lib/python3/site-packages/flaky/flaky_pytest_plugin.py:146>, <TracebackEntry /usr/lib/python3/site-packages/pluggy/_hooks.py:513>, <TracebackEntry /usr/lib/python3/site-packages/pluggy/_manager.py:120>, <TracebackEntry /usr/lib/python3/site-packages/pluggy/_callers.py:182>, <TracebackEntry /usr/lib/python3/site-packages/pluggy/_result.py:100>, <TracebackEntry /usr/lib/python3/site-packages/pluggy/_callers.py:167>, <TracebackEntry /usr/lib/python3/site-packages/_pytest/threadexception.py:92>, <TracebackEntry /usr/lib/python3/site-packages/_pytest/threadexception.py:68>, <TracebackEntry /usr/lib/python3/site-packages/pluggy/_callers.py:167>, <TracebackEntry /usr/lib/python3/site-packages/_pytest/unraisableexception.py:95>, <TracebackEntry /usr/lib/python3/site-packages/_pytest/unraisableexception.py:70>, <TracebackEntry /usr/lib/python3/site-packages/pluggy/_callers.py:167>, <TracebackEntry /usr/lib/python3/site-packages/_pytest/logging.py:846>, <TracebackEntry /usr/lib/python3/site-packages/_pytest/logging.py:829>, <TracebackEntry /usr/lib/python3/site-packages/pluggy/_callers.py:167>, <TracebackEntry /usr/lib/python3/site-packages/_pytest/capture.py:898>, <TracebackEntry /usr/lib/python3/site-packages/pluggy/_callers.py:167>, <TracebackEntry /usr/lib/python3/site-packages/_pytest/skipping.py:257>, <TracebackEntry /usr/lib/python3/site-packages/pluggy/_callers.py:103>, <TracebackEntry /usr/lib/python3/site-packages/_pytest/runner.py:174>, <TracebackEntry /usr/lib/python3/site-packages/_pytest/python.py:1627>, <TracebackEntry /usr/lib/python3/site-packages/pluggy/_hooks.py:513>, <TracebackEntry /usr/lib/python3/site-packages/pluggy/_manager.py:120>, <TracebackEntry /usr/lib/python3/site-packages/pluggy/_callers.py:139>, <TracebackEntry /usr/lib/python3/site-packages/pluggy/_callers.py:103>, <TracebackEntry /usr/lib/python3/site-packages/_pytest/python.py:159>, <TracebackEntry /usr/src/RPM/BUILD/python3-module-spyder-kernels-2.5.2/spyder_kernels/console/tests/test_console_kernel.py:1169>, <TracebackEntry /usr/lib/python3/site-packages/jupyter_core/utils/__init__.py:165>, <TracebackEntry /usr/lib64/python3.12/asyncio/base_events.py:691>, <TracebackEntry /usr/lib/python3/site-packages/jupyter_client/client.py:151>, <TracebackEntry /usr/lib/python3/site-packages/jupyter_client/channels.py:232>]
	[<TracebackEntry /usr/lib/python3/site-packages/_pytest/runner.py:341>, <TracebackEntry /usr/lib/python3/site-packages/flaky/flaky_pytest_plugin.py:146>, <TracebackEntry /usr/lib/python3/site-packages/pluggy/_hooks.py:513>, <TracebackEntry /usr/lib/python3/site-packages/pluggy/_manager.py:120>, <TracebackEntry /usr/lib/python3/site-packages/pluggy/_callers.py:182>, <TracebackEntry /usr/lib/python3/site-packages/pluggy/_result.py:100>, <TracebackEntry /usr/lib/python3/site-packages/pluggy/_callers.py:167>, <TracebackEntry /usr/lib/python3/site-packages/_pytest/threadexception.py:92>, <TracebackEntry /usr/lib/python3/site-packages/_pytest/threadexception.py:68>, <TracebackEntry /usr/lib/python3/site-packages/pluggy/_callers.py:167>, <TracebackEntry /usr/lib/python3/site-packages/_pytest/unraisableexception.py:95>, <TracebackEntry /usr/lib/python3/site-packages/_pytest/unraisableexception.py:70>, <TracebackEntry /usr/lib/python3/site-packages/pluggy/_callers.py:167>, <TracebackEntry /usr/lib/python3/site-packages/_pytest/logging.py:846>, <TracebackEntry /usr/lib/python3/site-packages/_pytest/logging.py:829>, <TracebackEntry /usr/lib/python3/site-packages/pluggy/_callers.py:167>, <TracebackEntry /usr/lib/python3/site-packages/_pytest/capture.py:898>, <TracebackEntry /usr/lib/python3/site-packages/pluggy/_callers.py:167>, <TracebackEntry /usr/lib/python3/site-packages/_pytest/skipping.py:257>, <TracebackEntry /usr/lib/python3/site-packages/pluggy/_callers.py:103>, <TracebackEntry /usr/lib/python3/site-packages/_pytest/runner.py:174>, <TracebackEntry /usr/lib/python3/site-packages/_pytest/python.py:1627>, <TracebackEntry /usr/lib/python3/site-packages/pluggy/_hooks.py:513>, <TracebackEntry /usr/lib/python3/site-packages/pluggy/_manager.py:120>, <TracebackEntry /usr/lib/python3/site-packages/pluggy/_callers.py:139>, <TracebackEntry /usr/lib/python3/site-packages/pluggy/_callers.py:103>, <TracebackEntry /usr/lib/python3/site-packages/_pytest/python.py:159>, <TracebackEntry /usr/src/RPM/BUILD/python3-module-spyder-kernels-2.5.2/spyder_kernels/console/tests/test_console_kernel.py:1169>, <TracebackEntry /usr/lib/python3/site-packages/jupyter_core/utils/__init__.py:165>, <TracebackEntry /usr/lib64/python3.12/asyncio/base_events.py:691>, <TracebackEntry /usr/lib/python3/site-packages/jupyter_client/client.py:151>, <TracebackEntry /usr/lib/python3/site-packages/jupyter_client/channels.py:232>]
	[<TracebackEntry /usr/lib/python3/site-packages/_pytest/runner.py:341>, <TracebackEntry /usr/lib/python3/site-packages/flaky/flaky_pytest_plugin.py:146>, <TracebackEntry /usr/lib/python3/site-packages/pluggy/_hooks.py:513>, <TracebackEntry /usr/lib/python3/site-packages/pluggy/_manager.py:120>, <TracebackEntry /usr/lib/python3/site-packages/pluggy/_callers.py:182>, <TracebackEntry /usr/lib/python3/site-packages/pluggy/_result.py:100>, <TracebackEntry /usr/lib/python3/site-packages/pluggy/_callers.py:167>, <TracebackEntry /usr/lib/python3/site-packages/_pytest/threadexception.py:92>, <TracebackEntry /usr/lib/python3/site-packages/_pytest/threadexception.py:68>, <TracebackEntry /usr/lib/python3/site-packages/pluggy/_callers.py:167>, <TracebackEntry /usr/lib/python3/site-packages/_pytest/unraisableexception.py:95>, <TracebackEntry /usr/lib/python3/site-packages/_pytest/unraisableexception.py:70>, <TracebackEntry /usr/lib/python3/site-packages/pluggy/_callers.py:167>, <TracebackEntry /usr/lib/python3/site-packages/_pytest/logging.py:846>, <TracebackEntry /usr/lib/python3/site-packages/_pytest/logging.py:829>, <TracebackEntry /usr/lib/python3/site-packages/pluggy/_callers.py:167>, <TracebackEntry /usr/lib/python3/site-packages/_pytest/capture.py:898>, <TracebackEntry /usr/lib/python3/site-packages/pluggy/_callers.py:167>, <TracebackEntry /usr/lib/python3/site-packages/_pytest/skipping.py:257>, <TracebackEntry /usr/lib/python3/site-packages/pluggy/_callers.py:103>, <TracebackEntry /usr/lib/python3/site-packages/_pytest/runner.py:174>, <TracebackEntry /usr/lib/python3/site-packages/_pytest/python.py:1627>, <TracebackEntry /usr/lib/python3/site-packages/pluggy/_hooks.py:513>, <TracebackEntry /usr/lib/python3/site-packages/pluggy/_manager.py:120>, <TracebackEntry /usr/lib/python3/site-packages/pluggy/_callers.py:139>, <TracebackEntry /usr/lib/python3/site-packages/pluggy/_callers.py:103>, <TracebackEntry /usr/lib/python3/site-packages/_pytest/python.py:159>, <TracebackEntry /usr/src/RPM/BUILD/python3-module-spyder-kernels-2.5.2/spyder_kernels/console/tests/test_console_kernel.py:1169>, <TracebackEntry /usr/lib/python3/site-packages/jupyter_core/utils/__init__.py:165>, <TracebackEntry /usr/lib64/python3.12/asyncio/base_events.py:691>, <TracebackEntry /usr/lib/python3/site-packages/jupyter_client/client.py:151>, <TracebackEntry /usr/lib/python3/site-packages/jupyter_client/channels.py:232>]






===End Flaky Test Report===
===End Flaky Test Report===
===End Flaky Test Report===
===End Flaky Test Report===
===End Flaky Test Report===
===End Flaky Test Report===
=========================== short test summary info ============================
=========================== short test summary info ============================
=========================== short test summary info ============================
=========================== short test summary info ============================
=========================== short test summary info ============================
=========================== short test summary info ============================
SKIPPED [1] spyder_kernels/console/tests/test_console_kernel.py:543: Doesn't work with pip packages
SKIPPED [1] spyder_kernels/console/tests/test_console_kernel.py:543: Doesn't work with pip packages
SKIPPED [1] spyder_kernels/console/tests/test_console_kernel.py:543: Doesn't work with pip packages
SKIPPED [1] spyder_kernels/console/tests/test_console_kernel.py:543: Doesn't work with pip packages
SKIPPED [1] spyder_kernels/console/tests/test_console_kernel.py:543: Doesn't work with pip packages
SKIPPED [4] spyder_kernels/console/tests/test_console_kernel.py:1106: Doesn't work with pip packages
SKIPPED [4] spyder_kernels/console/tests/test_console_kernel.py:1106: Doesn't work with pip packages
SKIPPED [4] spyder_kernels/console/tests/test_console_kernel.py:1106: Doesn't work with pip packages
SKIPPED [4] spyder_kernels/console/tests/test_console_kernel.py:1106: Doesn't work with pip packages
SKIPPED [4] spyder_kernels/console/tests/test_console_kernel.py:1106: Doesn't work with pip packages
FAILED spyder_kernels/console/tests/test_console_kernel.py::test_debug_namespace
FAILED spyder_kernels/console/tests/test_console_kernel.py::test_debug_namespace
FAILED spyder_kernels/console/tests/test_console_kernel.py::test_debug_namespace
FAILED spyder_kernels/console/tests/test_console_kernel.py::test_debug_namespace
FAILED spyder_kernels/console/tests/test_console_kernel.py::test_debug_namespace
======= 1 failed, 92 passed, 5 skipped, 11 warnings in 133.11s (0:02:13) =======
======= 1 failed, 92 passed, 5 skipped, 11 warnings in 133.11s (0:02:13) =======
======= 1 failed, 92 passed, 5 skipped, 11 warnings in 133.11s (0:02:13) =======
======= 1 failed, 92 passed, 5 skipped, 11 warnings in 133.11s (0:02:13) =======
======= 1 failed, 92 passed, 5 skipped, 11 warnings in 133.11s (0:02:13) =======
INFO     : Command's result: FAILURE
INFO     : Command's result: FAILURE
INFO     : Command's result: FAILURE
INFO     : Command's result: FAILURE
INFO     : Command's error: Command '['xvfb-run', '--', 'pytest', '-vra']' returned non-zero exit status 1.
INFO     : Command's error: Command '['xvfb-run', '--', 'pytest', '-vra']' returned non-zero exit status 1.
INFO     : Command's error: Command '['xvfb-run', '--', 'pytest', '-vra']' returned non-zero exit status 1.
INFO     : Command's error: Command '['xvfb-run', '--', 'pytest', '-vra']' returned non-zero exit status 1.
INFO     : Command's error: Command '['xvfb-run', '--', 'pytest', '-vra']' returned non-zero exit status 1.
error: Bad exit status from /usr/src/tmp/rpm-tmp.15106 (%check)
error: Bad exit status from /usr/src/tmp/rpm-tmp.15106 (%check)
error: Bad exit status from /usr/src/tmp/rpm-tmp.15106 (%check)
error: Bad exit status from /usr/src/tmp/rpm-tmp.15106 (%check)
error: Bad exit status from /usr/src/tmp/rpm-tmp.15106 (%check)










RPM build errors:
RPM build errors:
RPM build errors:
RPM build errors:
RPM build errors:
    File /usr/src/RPM/SOURCES/python3-module-spyder-kernels-2.5.2-alt.patch is smaller than 8 bytes
    File /usr/src/RPM/SOURCES/python3-module-spyder-kernels-2.5.2-alt.patch is smaller than 8 bytes
    File /usr/src/RPM/SOURCES/python3-module-spyder-kernels-2.5.2-alt.patch is smaller than 8 bytes
    File /usr/src/RPM/SOURCES/python3-module-spyder-kernels-2.5.2-alt.patch is smaller than 8 bytes
    File /usr/src/RPM/SOURCES/python3-module-spyder-kernels-2.5.2-alt.patch is smaller than 8 bytes
    Bad exit status from /usr/src/tmp/rpm-tmp.15106 (%check)
    Bad exit status from /usr/src/tmp/rpm-tmp.15106 (%check)
    Bad exit status from /usr/src/tmp/rpm-tmp.15106 (%check)
    Bad exit status from /usr/src/tmp/rpm-tmp.15106 (%check)
    Bad exit status from /usr/src/tmp/rpm-tmp.15106 (%check)
Command exited with non-zero status 1
Command exited with non-zero status 1
Command exited with non-zero status 1
Command exited with non-zero status 1
Command exited with non-zero status 1
55.21user 4.38system 2:20.44elapsed 42%CPU (0avgtext+0avgdata 319192maxresident)k
55.21user 4.38system 2:20.44elapsed 42%CPU (0avgtext+0avgdata 319192maxresident)k
55.21user 4.38system 2:20.44elapsed 42%CPU (0avgtext+0avgdata 319192maxresident)k
55.21user 4.38system 2:20.44elapsed 42%CPU (0avgtext+0avgdata 319192maxresident)k
0inputs+0outputs (0major+500561minor)pagefaults 0swaps
0inputs+0outputs (0major+500561minor)pagefaults 0swaps
0inputs+0outputs (0major+500561minor)pagefaults 0swaps
hsh-rebuild: rebuild of `python3-module-spyder-kernels-2.5.2-alt1.src.rpm' failed.
hsh-rebuild: rebuild of `python3-module-spyder-kernels-2.5.2-alt1.src.rpm' failed.
hsh-rebuild: rebuild of `python3-module-spyder-kernels-2.5.2-alt1.src.rpm' failed.
Command exited with non-zero status 1
Command exited with non-zero status 1
11.80user 3.20system 3:13.08elapsed 7%CPU (0avgtext+0avgdata 142544maxresident)k
99032inputs+0outputs (0major+356050minor)pagefaults 0swaps
