tests/test_expand_tabs.py::test_expand_tabs_inline[1234\tbar-1234    bar] PASSED [ 47%]
tests/test_expand_tabs.py::test_expand_tabs_inline[\U0001f4a9\tbar-\U0001f4a9  bar] PASSED [ 47%]
tests/test_expand_tabs.py::test_expand_tabs_inline[\U0001f4a9\tbar-\U0001f4a9  bar] PASSED [ 47%]
tests/test_expand_tabs.py::test_expand_tabs_inline[\U0001f4a9\U0001f4a9\tbar-\U0001f4a9\U0001f4a9    bar] PASSED [ 47%]
tests/test_expand_tabs.py::test_expand_tabs_inline[\U0001f4a9\U0001f4a9\tbar-\U0001f4a9\U0001f4a9    bar] PASSED [ 47%]
tests/test_expand_tabs.py::test_expand_tabs_inline[\U0001f4a9\U0001f4a9\tbar-\U0001f4a9\U0001f4a9    bar] PASSED [ 47%]
tests/test_expand_tabs.py::test_expand_tabs_inline[\U0001f4a9\U0001f4a9\U0001f4a9\tbar-\U0001f4a9\U0001f4a9\U0001f4a9  bar] PASSED [ 47%]
tests/test_expand_tabs.py::test_expand_tabs_inline[\U0001f4a9\U0001f4a9\U0001f4a9\tbar-\U0001f4a9\U0001f4a9\U0001f4a9  bar] PASSED [ 47%]
tests/test_expand_tabs.py::test_expand_tabs_inline[\U0001f4a9\U0001f4a9\U0001f4a9\tbar-\U0001f4a9\U0001f4a9\U0001f4a9  bar] PASSED [ 47%]
tests/test_expand_tabs.py::test_expand_tabs_inline[\U0001f4a9\U0001f4a9\U0001f4a9\tbar-\U0001f4a9\U0001f4a9\U0001f4a9  bar] PASSED [ 47%]
tests/test_expand_tabs.py::test_expand_tabs_inline[F\U0001f4a9\tbar-F\U0001f4a9 bar] PASSED [ 47%]
tests/test_expand_tabs.py::test_expand_tabs_inline[F\U0001f4a9\tbar-F\U0001f4a9 bar] PASSED [ 47%]
tests/test_expand_tabs.py::test_expand_tabs_inline[F\U0001f4a9\tbar-F\U0001f4a9 bar] PASSED [ 47%]
tests/test_expand_tabs.py::test_expand_tabs_inline[F\U0001f4a9\tbar-F\U0001f4a9 bar] PASSED [ 47%]
tests/test_expand_tabs.py::test_expand_tabs_inline[F\U0001f4a9\tbar-F\U0001f4a9 bar] PASSED [ 47%]
tests/test_expand_tabs.py::test_expand_tabs_inline[F\U0001f4a9O\tbar-F\U0001f4a9O    bar] PASSED [ 47%]
tests/test_expand_tabs.py::test_expand_tabs_inline[F\U0001f4a9O\tbar-F\U0001f4a9O    bar] PASSED [ 47%]
tests/test_expand_tabs.py::test_expand_tabs_inline[F\U0001f4a9O\tbar-F\U0001f4a9O    bar] PASSED [ 47%]
tests/test_expand_tabs.py::test_expand_tabs_inline[F\U0001f4a9O\tbar-F\U0001f4a9O    bar] PASSED [ 47%]
tests/test_expand_tabs.py::test_expand_tabs_inline[F\U0001f4a9O\tbar-F\U0001f4a9O    bar] PASSED [ 47%]
tests/test_expand_tabs.py::test_expand_tabs_inline[F\U0001f4a9O\tbar-F\U0001f4a9O    bar] PASSED [ 47%]
tests/test_expand_tabs.py::test_get_tab_widths PASSED                    [ 47%]
tests/test_expand_tabs.py::test_get_tab_widths PASSED                    [ 47%]
tests/test_expand_tabs.py::test_get_tab_widths PASSED                    [ 47%]
tests/test_expand_tabs.py::test_get_tab_widths PASSED                    [ 47%]
tests/test_expand_tabs.py::test_get_tab_widths PASSED                    [ 47%]
tests/test_expand_tabs.py::test_get_tab_widths PASSED                    [ 47%]
tests/test_expand_tabs.py::test_get_tab_widths PASSED                    [ 47%]
tests/test_file_monitor.py::test_repr PASSED                             [ 47%]
tests/test_file_monitor.py::test_repr PASSED                             [ 47%]
tests/test_file_monitor.py::test_repr PASSED                             [ 47%]
tests/test_file_monitor.py::test_repr PASSED                             [ 47%]
tests/test_file_monitor.py::test_repr PASSED                             [ 47%]
tests/test_file_monitor.py::test_repr PASSED                             [ 47%]
tests/test_file_monitor.py::test_repr PASSED                             [ 47%]
tests/test_file_monitor.py::test_repr PASSED                             [ 47%]
tests/test_file_monitor.py::test_file_never_found PASSED                 [ 47%]
tests/test_file_monitor.py::test_file_never_found PASSED                 [ 47%]
tests/test_file_monitor.py::test_file_never_found PASSED                 [ 47%]
tests/test_file_monitor.py::test_file_never_found PASSED                 [ 47%]
tests/test_file_monitor.py::test_file_never_found PASSED                 [ 47%]
tests/test_file_monitor.py::test_file_never_found PASSED                 [ 47%]
tests/test_file_monitor.py::test_file_never_found PASSED                 [ 47%]
tests/test_file_monitor.py::test_file_never_found PASSED                 [ 47%]
tests/test_file_monitor.py::test_file_never_found PASSED                 [ 47%]
tests/test_file_monitor.py::test_file_deletion PASSED                    [ 47%]
tests/test_file_monitor.py::test_file_deletion PASSED                    [ 47%]
tests/test_file_monitor.py::test_file_deletion PASSED                    [ 47%]
tests/test_file_monitor.py::test_file_deletion PASSED                    [ 47%]
tests/test_file_monitor.py::test_file_deletion PASSED                    [ 47%]
tests/test_file_monitor.py::test_file_deletion PASSED                    [ 47%]
tests/test_file_monitor.py::test_file_deletion PASSED                    [ 47%]
tests/test_file_monitor.py::test_file_deletion PASSED                    [ 47%]
tests/test_file_monitor.py::test_file_deletion PASSED                    [ 47%]
tests/test_file_monitor.py::test_file_deletion PASSED                    [ 47%]
tests/test_focus.py::test_focus_chain FAILED                             [ 47%]
tests/test_focus.py::test_focus_chain FAILED                             [ 47%]
tests/test_focus.py::test_focus_chain FAILED                             [ 47%]
tests/test_focus.py::test_focus_chain FAILED                             [ 47%]
tests/test_focus.py::test_focus_chain FAILED                             [ 47%]
tests/test_focus.py::test_focus_chain FAILED                             [ 47%]
tests/test_focus.py::test_focus_chain FAILED                             [ 47%]
tests/test_focus.py::test_focus_chain FAILED                             [ 47%]
tests/test_focus.py::test_focus_chain FAILED                             [ 47%]
tests/test_focus.py::test_focus_chain FAILED                             [ 47%]
tests/test_focus.py::test_focus_chain FAILED                             [ 47%]
tests/test_focus.py::test_allow_focus FAILED                             [ 47%]
tests/test_focus.py::test_allow_focus FAILED                             [ 47%]
tests/test_focus.py::test_allow_focus FAILED                             [ 47%]
tests/test_focus.py::test_allow_focus FAILED                             [ 47%]
tests/test_focus.py::test_allow_focus FAILED                             [ 47%]
tests/test_focus.py::test_allow_focus FAILED                             [ 47%]
tests/test_focus.py::test_allow_focus FAILED                             [ 47%]
tests/test_focus.py::test_allow_focus FAILED                             [ 47%]
tests/test_focus.py::test_allow_focus FAILED                             [ 47%]
tests/test_focus.py::test_allow_focus FAILED                             [ 47%]
tests/test_focus.py::test_allow_focus FAILED                             [ 47%]
tests/test_focus.py::test_focus_next_and_previous ERROR                  [ 47%]
tests/test_focus.py::test_focus_next_and_previous ERROR                  [ 47%]
tests/test_focus.py::test_focus_next_and_previous ERROR                  [ 47%]
tests/test_focus.py::test_focus_next_and_previous ERROR                  [ 47%]
tests/test_focus.py::test_focus_next_and_previous ERROR                  [ 47%]
tests/test_focus.py::test_focus_next_and_previous ERROR                  [ 47%]
tests/test_focus.py::test_focus_next_and_previous ERROR                  [ 47%]
tests/test_focus.py::test_focus_next_and_previous ERROR                  [ 47%]
tests/test_focus.py::test_focus_next_and_previous ERROR                  [ 47%]
tests/test_focus.py::test_focus_next_and_previous ERROR                  [ 47%]
tests/test_focus.py::test_focus_next_and_previous ERROR                  [ 47%]
tests/test_focus.py::test_focus_next_wrap_around ERROR                   [ 47%]
tests/test_focus.py::test_focus_next_wrap_around ERROR                   [ 47%]
tests/test_focus.py::test_focus_next_wrap_around ERROR                   [ 47%]
tests/test_focus.py::test_focus_next_wrap_around ERROR                   [ 47%]
tests/test_focus.py::test_focus_next_wrap_around ERROR                   [ 47%]
tests/test_focus.py::test_focus_next_wrap_around ERROR                   [ 47%]
tests/test_focus.py::test_focus_next_wrap_around ERROR                   [ 47%]
tests/test_focus.py::test_focus_next_wrap_around ERROR                   [ 47%]
tests/test_focus.py::test_focus_next_wrap_around ERROR                   [ 47%]
tests/test_focus.py::test_focus_next_wrap_around ERROR                   [ 47%]
tests/test_focus.py::test_focus_next_wrap_around ERROR                   [ 47%]
tests/test_focus.py::test_focus_previous_wrap_around ERROR               [ 47%]
tests/test_focus.py::test_focus_previous_wrap_around ERROR               [ 47%]
tests/test_focus.py::test_focus_previous_wrap_around ERROR               [ 47%]
tests/test_focus.py::test_focus_previous_wrap_around ERROR               [ 47%]
tests/test_focus.py::test_focus_previous_wrap_around ERROR               [ 47%]
tests/test_focus.py::test_focus_previous_wrap_around ERROR               [ 47%]
tests/test_focus.py::test_focus_previous_wrap_around ERROR               [ 47%]
tests/test_focus.py::test_focus_previous_wrap_around ERROR               [ 47%]
tests/test_focus.py::test_focus_previous_wrap_around ERROR               [ 47%]
tests/test_focus.py::test_focus_previous_wrap_around ERROR               [ 47%]
tests/test_focus.py::test_focus_previous_wrap_around ERROR               [ 47%]
tests/test_focus.py::test_wrap_around_selector ERROR                     [ 47%]
tests/test_focus.py::test_wrap_around_selector ERROR                     [ 47%]
tests/test_focus.py::test_wrap_around_selector ERROR                     [ 47%]
tests/test_focus.py::test_wrap_around_selector ERROR                     [ 47%]
tests/test_focus.py::test_wrap_around_selector ERROR                     [ 47%]
tests/test_focus.py::test_wrap_around_selector ERROR                     [ 47%]
tests/test_focus.py::test_wrap_around_selector ERROR                     [ 47%]
tests/test_focus.py::test_wrap_around_selector ERROR                     [ 47%]
tests/test_focus.py::test_wrap_around_selector ERROR                     [ 47%]
tests/test_focus.py::test_wrap_around_selector ERROR                     [ 47%]
tests/test_focus.py::test_wrap_around_selector ERROR                     [ 47%]
tests/test_focus.py::test_no_focus_empty_selector ERROR                  [ 47%]
tests/test_focus.py::test_no_focus_empty_selector ERROR                  [ 47%]
tests/test_focus.py::test_no_focus_empty_selector ERROR                  [ 47%]
tests/test_focus.py::test_no_focus_empty_selector ERROR                  [ 47%]
tests/test_focus.py::test_no_focus_empty_selector ERROR                  [ 47%]
tests/test_focus.py::test_no_focus_empty_selector ERROR                  [ 47%]
tests/test_focus.py::test_no_focus_empty_selector ERROR                  [ 47%]
tests/test_focus.py::test_no_focus_empty_selector ERROR                  [ 47%]
tests/test_focus.py::test_no_focus_empty_selector ERROR                  [ 47%]
tests/test_focus.py::test_no_focus_empty_selector ERROR                  [ 47%]
tests/test_focus.py::test_no_focus_empty_selector ERROR                  [ 47%]
tests/test_focus.py::test_focus_next_and_previous_with_type_selector ERROR [ 47%]
tests/test_focus.py::test_focus_next_and_previous_with_type_selector ERROR [ 47%]
tests/test_focus.py::test_focus_next_and_previous_with_type_selector ERROR [ 47%]
tests/test_focus.py::test_focus_next_and_previous_with_type_selector ERROR [ 47%]
tests/test_focus.py::test_focus_next_and_previous_with_type_selector ERROR [ 47%]
tests/test_focus.py::test_focus_next_and_previous_with_type_selector ERROR [ 47%]
tests/test_focus.py::test_focus_next_and_previous_with_type_selector ERROR [ 47%]
tests/test_focus.py::test_focus_next_and_previous_with_type_selector ERROR [ 47%]
tests/test_focus.py::test_focus_next_and_previous_with_type_selector ERROR [ 47%]
tests/test_focus.py::test_focus_next_and_previous_with_type_selector ERROR [ 47%]
tests/test_focus.py::test_focus_next_and_previous_with_type_selector ERROR [ 47%]
tests/test_focus.py::test_focus_next_and_previous_with_str_selector ERROR [ 47%]
tests/test_focus.py::test_focus_next_and_previous_with_str_selector ERROR [ 47%]
tests/test_focus.py::test_focus_next_and_previous_with_str_selector ERROR [ 47%]
tests/test_focus.py::test_focus_next_and_previous_with_str_selector ERROR [ 47%]
tests/test_focus.py::test_focus_next_and_previous_with_str_selector ERROR [ 47%]
tests/test_focus.py::test_focus_next_and_previous_with_str_selector ERROR [ 47%]
tests/test_focus.py::test_focus_next_and_previous_with_str_selector ERROR [ 47%]
tests/test_focus.py::test_focus_next_and_previous_with_str_selector ERROR [ 47%]
tests/test_focus.py::test_focus_next_and_previous_with_str_selector ERROR [ 47%]
tests/test_focus.py::test_focus_next_and_previous_with_str_selector ERROR [ 47%]
tests/test_focus.py::test_focus_next_and_previous_with_str_selector ERROR [ 47%]
tests/test_focus.py::test_focus_next_and_previous_with_type_selector_without_self FAILED [ 47%]
tests/test_focus.py::test_focus_next_and_previous_with_type_selector_without_self FAILED [ 47%]
tests/test_focus.py::test_focus_next_and_previous_with_type_selector_without_self FAILED [ 47%]
tests/test_focus.py::test_focus_next_and_previous_with_type_selector_without_self FAILED [ 47%]
tests/test_focus.py::test_focus_next_and_previous_with_type_selector_without_self FAILED [ 47%]
tests/test_focus.py::test_focus_next_and_previous_with_type_selector_without_self FAILED [ 47%]
tests/test_focus.py::test_focus_next_and_previous_with_type_selector_without_self FAILED [ 47%]
tests/test_focus.py::test_focus_next_and_previous_with_type_selector_without_self FAILED [ 47%]
tests/test_focus.py::test_focus_next_and_previous_with_type_selector_without_self FAILED [ 47%]
tests/test_focus.py::test_focus_next_and_previous_with_type_selector_without_self FAILED [ 47%]
tests/test_focus.py::test_focus_next_and_previous_with_type_selector_without_self FAILED [ 47%]
tests/test_focus.py::test_focus_next_and_previous_with_str_selector_without_self ERROR [ 48%]
tests/test_focus.py::test_focus_next_and_previous_with_str_selector_without_self ERROR [ 48%]
tests/test_focus.py::test_focus_next_and_previous_with_str_selector_without_self ERROR [ 48%]
tests/test_focus.py::test_focus_next_and_previous_with_str_selector_without_self ERROR [ 48%]
tests/test_focus.py::test_focus_next_and_previous_with_str_selector_without_self ERROR [ 48%]
tests/test_focus.py::test_focus_next_and_previous_with_str_selector_without_self ERROR [ 48%]
tests/test_focus.py::test_focus_next_and_previous_with_str_selector_without_self ERROR [ 48%]
tests/test_focus.py::test_focus_next_and_previous_with_str_selector_without_self ERROR [ 48%]
tests/test_focus.py::test_focus_next_and_previous_with_str_selector_without_self ERROR [ 48%]
tests/test_focus.py::test_focus_next_and_previous_with_str_selector_without_self ERROR [ 48%]
tests/test_focus.py::test_focus_next_and_previous_with_str_selector_without_self ERROR [ 48%]
tests/test_focus.py::test_focus_does_not_move_to_invisible_widgets PASSED [ 48%]
tests/test_focus.py::test_focus_does_not_move_to_invisible_widgets PASSED [ 48%]
tests/test_focus.py::test_focus_does_not_move_to_invisible_widgets PASSED [ 48%]
tests/test_focus.py::test_focus_does_not_move_to_invisible_widgets PASSED [ 48%]
tests/test_focus.py::test_focus_does_not_move_to_invisible_widgets PASSED [ 48%]
tests/test_focus.py::test_focus_does_not_move_to_invisible_widgets PASSED [ 48%]
tests/test_focus.py::test_focus_does_not_move_to_invisible_widgets PASSED [ 48%]
tests/test_focus.py::test_focus_does_not_move_to_invisible_widgets PASSED [ 48%]
tests/test_focus.py::test_focus_does_not_move_to_invisible_widgets PASSED [ 48%]
tests/test_focus.py::test_focus_does_not_move_to_invisible_widgets PASSED [ 48%]
tests/test_focus.py::test_focus_moves_to_visible_widgets_inside_invisible_containers PASSED [ 48%]
tests/test_focus.py::test_focus_moves_to_visible_widgets_inside_invisible_containers PASSED [ 48%]
tests/test_focus.py::test_focus_moves_to_visible_widgets_inside_invisible_containers PASSED [ 48%]
tests/test_focus.py::test_focus_moves_to_visible_widgets_inside_invisible_containers PASSED [ 48%]
tests/test_focus.py::test_focus_moves_to_visible_widgets_inside_invisible_containers PASSED [ 48%]
tests/test_focus.py::test_focus_moves_to_visible_widgets_inside_invisible_containers PASSED [ 48%]
tests/test_focus.py::test_focus_moves_to_visible_widgets_inside_invisible_containers PASSED [ 48%]
tests/test_focus.py::test_focus_moves_to_visible_widgets_inside_invisible_containers PASSED [ 48%]
tests/test_focus.py::test_focus_moves_to_visible_widgets_inside_invisible_containers PASSED [ 48%]
tests/test_focus.py::test_focus_chain_handles_inherited_visibility PASSED [ 48%]
tests/test_focus.py::test_focus_chain_handles_inherited_visibility PASSED [ 48%]
tests/test_focus.py::test_focus_chain_handles_inherited_visibility PASSED [ 48%]
tests/test_focus.py::test_focus_chain_handles_inherited_visibility PASSED [ 48%]
tests/test_focus.py::test_focus_chain_handles_inherited_visibility PASSED [ 48%]
tests/test_focus.py::test_focus_chain_handles_inherited_visibility PASSED [ 48%]
tests/test_focus.py::test_focus_chain_handles_inherited_visibility PASSED [ 48%]
tests/test_focus.py::test_focus_chain_handles_inherited_visibility PASSED [ 48%]
tests/test_focus.py::test_mouse_down_gives_focus PASSED                  [ 48%]
tests/test_focus.py::test_mouse_down_gives_focus PASSED                  [ 48%]
tests/test_focus.py::test_mouse_down_gives_focus PASSED                  [ 48%]
tests/test_focus.py::test_mouse_down_gives_focus PASSED                  [ 48%]
tests/test_focus.py::test_mouse_down_gives_focus PASSED                  [ 48%]
tests/test_focus.py::test_mouse_down_gives_focus PASSED                  [ 48%]
tests/test_focus.py::test_mouse_down_gives_focus PASSED                  [ 48%]
tests/test_focus.py::test_mouse_up_does_not_give_focus PASSED            [ 48%]
tests/test_focus.py::test_mouse_up_does_not_give_focus PASSED            [ 48%]
tests/test_focus.py::test_mouse_up_does_not_give_focus PASSED            [ 48%]
tests/test_focus.py::test_mouse_up_does_not_give_focus PASSED            [ 48%]
tests/test_focus.py::test_mouse_up_does_not_give_focus PASSED            [ 48%]
tests/test_focus.py::test_mouse_up_does_not_give_focus PASSED            [ 48%]
tests/test_focus.py::test_focus_pseudo_class PASSED                      [ 48%]
tests/test_focus.py::test_focus_pseudo_class PASSED                      [ 48%]
tests/test_focus.py::test_focus_pseudo_class PASSED                      [ 48%]
tests/test_focus.py::test_focus_pseudo_class PASSED                      [ 48%]
tests/test_focus.py::test_focus_pseudo_class PASSED                      [ 48%]
tests/test_focus.py::test_get_focusable_widget_at PASSED                 [ 48%]
tests/test_focus.py::test_get_focusable_widget_at PASSED                 [ 48%]
tests/test_focus.py::test_get_focusable_widget_at PASSED                 [ 48%]
tests/test_focus.py::test_get_focusable_widget_at PASSED                 [ 48%]
tests/test_freeze.py::test_freeze PASSED                                 [ 48%]
tests/test_freeze.py::test_freeze PASSED                                 [ 48%]
tests/test_freeze.py::test_freeze PASSED                                 [ 48%]
tests/test_fuzzy.py::test_match PASSED                                   [ 48%]
tests/test_fuzzy.py::test_match PASSED                                   [ 48%]
tests/test_fuzzy.py::test_highlight PASSED                               [ 48%]
tests/workers/test_worker.py::test_progress_update PASSED                [ 99%]
tests/workers/test_worker.py::test_double_start PASSED                   [ 99%]
tests/workers/test_worker.py::test_self_referential_deadlock PASSED      [ 99%]
tests/workers/test_worker.py::test_wait_without_start PASSED             [ 99%]
tests/workers/test_worker_manager.py::test_worker_manager_init PASSED    [ 99%]
tests/workers/test_worker_manager.py::test_run_worker_async PASSED       [ 99%]
tests/workers/test_worker_manager.py::test_run_worker_thread_non_async PASSED [ 99%]
tests/workers/test_worker_manager.py::test_run_worker_thread_async PASSED [100%]

==================================== ERRORS ====================================
________________ ERROR at setup of test_focus_next_and_previous ________________

self = App(title='App', classes={'-dark-mode'}, pseudo_classes={'focus', 'dark'})
screen = Screen(), callback = None, wait_for_dismiss = False

    def push_screen(
        self,
        screen: Screen[ScreenResultType] | str,
        callback: ScreenResultCallbackType[ScreenResultType] | None = None,
        wait_for_dismiss: bool = False,
    ) -> AwaitMount | asyncio.Future[ScreenResultType]:
            raise TypeError(
                f"push_screen requires a Screen instance or str; not {screen!r}"
            )
    
        try:
>           loop = asyncio.get_running_loop()
E           RuntimeError: no running event loop

.run_venv/lib64/python3/site-packages/textual/app.py:2499: RuntimeError

During handling of the above exception, another exception occurred:

    @pytest.fixture
    def screen() -> Screen:
        app = App()
    
        with app._context():
>           app.push_screen(Screen())

tests/test_focus.py:27: 
_ _ _ _ _ _ _ _ _ _ _ _ _ _ _ _ _ _ _ _ _ _ _ _ _ _ _ _ _ _ _ _ _ _ _ _ _ _ _ _ 
_ _ _ _ _ _ _ _ _ _ _ _ _ _ _ _ _ _ _ _ _ _ _ _ _ _ _ _ _ _ _ _ _ _ _ _ _ _ _ _ 
.run_venv/lib64/python3/site-packages/textual/app.py:2502: in push_screen
    future: asyncio.Future[ScreenResultType] = asyncio.Future()
_ _ _ _ _ _ _ _ _ _ _ _ _ _ _ _ _ _ _ _ _ _ _ _ _ _ _ _ _ _ _ _ _ _ _ _ _ _ _ _ 

self = <asyncio.unix_events._UnixDefaultEventLoopPolicy object at 0x7f45f6bb5bb0>

    def get_event_loop(self):
        """Get the event loop for the current context.
    
        Returns an instance of EventLoop or raises an exception.
        """
        if (self._local._loop is None and
                not self._local._set_called and
                threading.current_thread() is threading.main_thread()):
            stacklevel = 2
            try:
                f = sys._getframe(1)
            except AttributeError:
                pass
            else:
            warnings.warn('There is no current event loop',
                          DeprecationWarning, stacklevel=stacklevel)
            self.set_event_loop(self.new_event_loop())
    
        if self._local._loop is None:
>           raise RuntimeError('There is no current event loop in thread %r.'
                               % threading.current_thread().name)
E           RuntimeError: There is no current event loop in thread 'MainThread'.

/usr/lib64/python3.12/asyncio/events.py:702: RuntimeError
________________ ERROR at setup of test_focus_next_wrap_around _________________

self = App(title='App', classes={'-dark-mode'}, pseudo_classes={'focus', 'dark'})
screen = Screen(), callback = None, wait_for_dismiss = False

    def push_screen(
        self,
        screen: Screen[ScreenResultType] | str,
        callback: ScreenResultCallbackType[ScreenResultType] | None = None,
        wait_for_dismiss: bool = False,
    ) -> AwaitMount | asyncio.Future[ScreenResultType]:
            raise TypeError(
                f"push_screen requires a Screen instance or str; not {screen!r}"
            )
    
        try:
>           loop = asyncio.get_running_loop()
E           RuntimeError: no running event loop

.run_venv/lib64/python3/site-packages/textual/app.py:2499: RuntimeError

During handling of the above exception, another exception occurred:

    @pytest.fixture
    def screen() -> Screen:
        app = App()
    
        with app._context():
>           app.push_screen(Screen())

tests/test_focus.py:27: 
_ _ _ _ _ _ _ _ _ _ _ _ _ _ _ _ _ _ _ _ _ _ _ _ _ _ _ _ _ _ _ _ _ _ _ _ _ _ _ _ 
_ _ _ _ _ _ _ _ _ _ _ _ _ _ _ _ _ _ _ _ _ _ _ _ _ _ _ _ _ _ _ _ _ _ _ _ _ _ _ _ 
.run_venv/lib64/python3/site-packages/textual/app.py:2502: in push_screen
    future: asyncio.Future[ScreenResultType] = asyncio.Future()
_ _ _ _ _ _ _ _ _ _ _ _ _ _ _ _ _ _ _ _ _ _ _ _ _ _ _ _ _ _ _ _ _ _ _ _ _ _ _ _ 

self = <asyncio.unix_events._UnixDefaultEventLoopPolicy object at 0x7f45f6bb5bb0>

    def get_event_loop(self):
        """Get the event loop for the current context.
    
        Returns an instance of EventLoop or raises an exception.
        """
        if (self._local._loop is None and
                not self._local._set_called and
                threading.current_thread() is threading.main_thread()):
            stacklevel = 2
            try:
                f = sys._getframe(1)
            except AttributeError:
                pass
            else:
            warnings.warn('There is no current event loop',
                          DeprecationWarning, stacklevel=stacklevel)
            self.set_event_loop(self.new_event_loop())
    
        if self._local._loop is None:
>           raise RuntimeError('There is no current event loop in thread %r.'
                               % threading.current_thread().name)
E           RuntimeError: There is no current event loop in thread 'MainThread'.

/usr/lib64/python3.12/asyncio/events.py:702: RuntimeError
______________ ERROR at setup of test_focus_previous_wrap_around _______________

self = App(title='App', classes={'-dark-mode'}, pseudo_classes={'focus', 'dark'})
screen = Screen(), callback = None, wait_for_dismiss = False

    def push_screen(
        self,
        screen: Screen[ScreenResultType] | str,
        callback: ScreenResultCallbackType[ScreenResultType] | None = None,
        wait_for_dismiss: bool = False,
    ) -> AwaitMount | asyncio.Future[ScreenResultType]:
            raise TypeError(
                f"push_screen requires a Screen instance or str; not {screen!r}"
            )
    
        try:
>           loop = asyncio.get_running_loop()
E           RuntimeError: no running event loop

.run_venv/lib64/python3/site-packages/textual/app.py:2499: RuntimeError

During handling of the above exception, another exception occurred:

    @pytest.fixture
    def screen() -> Screen:
        app = App()
    
        with app._context():
>           app.push_screen(Screen())

tests/test_focus.py:27: 
_ _ _ _ _ _ _ _ _ _ _ _ _ _ _ _ _ _ _ _ _ _ _ _ _ _ _ _ _ _ _ _ _ _ _ _ _ _ _ _ 
_ _ _ _ _ _ _ _ _ _ _ _ _ _ _ _ _ _ _ _ _ _ _ _ _ _ _ _ _ _ _ _ _ _ _ _ _ _ _ _ 
.run_venv/lib64/python3/site-packages/textual/app.py:2502: in push_screen
    future: asyncio.Future[ScreenResultType] = asyncio.Future()
_ _ _ _ _ _ _ _ _ _ _ _ _ _ _ _ _ _ _ _ _ _ _ _ _ _ _ _ _ _ _ _ _ _ _ _ _ _ _ _ 

self = <asyncio.unix_events._UnixDefaultEventLoopPolicy object at 0x7f45f6bb5bb0>

    def get_event_loop(self):
        """Get the event loop for the current context.
    
        Returns an instance of EventLoop or raises an exception.
        """
        if (self._local._loop is None and
                not self._local._set_called and
                threading.current_thread() is threading.main_thread()):
            stacklevel = 2
            try:
                f = sys._getframe(1)
            except AttributeError:
                pass
            else:
            warnings.warn('There is no current event loop',
                          DeprecationWarning, stacklevel=stacklevel)
            self.set_event_loop(self.new_event_loop())
    
        if self._local._loop is None:
>           raise RuntimeError('There is no current event loop in thread %r.'
                               % threading.current_thread().name)
E           RuntimeError: There is no current event loop in thread 'MainThread'.

/usr/lib64/python3.12/asyncio/events.py:702: RuntimeError
_________________ ERROR at setup of test_wrap_around_selector __________________

self = App(title='App', classes={'-dark-mode'}, pseudo_classes={'focus', 'dark'})
screen = Screen(), callback = None, wait_for_dismiss = False

    def push_screen(
        self,
        screen: Screen[ScreenResultType] | str,
        callback: ScreenResultCallbackType[ScreenResultType] | None = None,
        wait_for_dismiss: bool = False,
    ) -> AwaitMount | asyncio.Future[ScreenResultType]:
            raise TypeError(
                f"push_screen requires a Screen instance or str; not {screen!r}"
            )
    
        try:
>           loop = asyncio.get_running_loop()
E           RuntimeError: no running event loop

.run_venv/lib64/python3/site-packages/textual/app.py:2499: RuntimeError

During handling of the above exception, another exception occurred:

    @pytest.fixture
    def screen() -> Screen:
        app = App()
    
        with app._context():
>           app.push_screen(Screen())

tests/test_focus.py:27: 
_ _ _ _ _ _ _ _ _ _ _ _ _ _ _ _ _ _ _ _ _ _ _ _ _ _ _ _ _ _ _ _ _ _ _ _ _ _ _ _ 
_ _ _ _ _ _ _ _ _ _ _ _ _ _ _ _ _ _ _ _ _ _ _ _ _ _ _ _ _ _ _ _ _ _ _ _ _ _ _ _ 
.run_venv/lib64/python3/site-packages/textual/app.py:2502: in push_screen
    future: asyncio.Future[ScreenResultType] = asyncio.Future()
_ _ _ _ _ _ _ _ _ _ _ _ _ _ _ _ _ _ _ _ _ _ _ _ _ _ _ _ _ _ _ _ _ _ _ _ _ _ _ _ 

self = <asyncio.unix_events._UnixDefaultEventLoopPolicy object at 0x7f45f6bb5bb0>

    def get_event_loop(self):
        """Get the event loop for the current context.
    
        Returns an instance of EventLoop or raises an exception.
        """
        if (self._local._loop is None and
                not self._local._set_called and
                threading.current_thread() is threading.main_thread()):
            stacklevel = 2
            try:
                f = sys._getframe(1)
            except AttributeError:
                pass
            else:
            warnings.warn('There is no current event loop',
                          DeprecationWarning, stacklevel=stacklevel)
            self.set_event_loop(self.new_event_loop())
    
        if self._local._loop is None:
>           raise RuntimeError('There is no current event loop in thread %r.'
                               % threading.current_thread().name)
E           RuntimeError: There is no current event loop in thread 'MainThread'.

/usr/lib64/python3.12/asyncio/events.py:702: RuntimeError
________________ ERROR at setup of test_no_focus_empty_selector ________________

self = App(title='App', classes={'-dark-mode'}, pseudo_classes={'focus', 'dark'})
screen = Screen(), callback = None, wait_for_dismiss = False

    def push_screen(
        self,
        screen: Screen[ScreenResultType] | str,
        callback: ScreenResultCallbackType[ScreenResultType] | None = None,
        wait_for_dismiss: bool = False,
    ) -> AwaitMount | asyncio.Future[ScreenResultType]:
            raise TypeError(
                f"push_screen requires a Screen instance or str; not {screen!r}"
            )
    
        try:
>           loop = asyncio.get_running_loop()
E           RuntimeError: no running event loop

.run_venv/lib64/python3/site-packages/textual/app.py:2499: RuntimeError

During handling of the above exception, another exception occurred:

    @pytest.fixture
    def screen() -> Screen:
        app = App()
    
        with app._context():
>           app.push_screen(Screen())

tests/test_focus.py:27: 
_ _ _ _ _ _ _ _ _ _ _ _ _ _ _ _ _ _ _ _ _ _ _ _ _ _ _ _ _ _ _ _ _ _ _ _ _ _ _ _ 
_ _ _ _ _ _ _ _ _ _ _ _ _ _ _ _ _ _ _ _ _ _ _ _ _ _ _ _ _ _ _ _ _ _ _ _ _ _ _ _ 
.run_venv/lib64/python3/site-packages/textual/app.py:2502: in push_screen
    future: asyncio.Future[ScreenResultType] = asyncio.Future()
_ _ _ _ _ _ _ _ _ _ _ _ _ _ _ _ _ _ _ _ _ _ _ _ _ _ _ _ _ _ _ _ _ _ _ _ _ _ _ _ 

self = <asyncio.unix_events._UnixDefaultEventLoopPolicy object at 0x7f45f6bb5bb0>

    def get_event_loop(self):
        """Get the event loop for the current context.
    
        Returns an instance of EventLoop or raises an exception.
        """
        if (self._local._loop is None and
                not self._local._set_called and
                threading.current_thread() is threading.main_thread()):
            stacklevel = 2
            try:
                f = sys._getframe(1)
            except AttributeError:
                pass
            else:
            warnings.warn('There is no current event loop',
                          DeprecationWarning, stacklevel=stacklevel)
            self.set_event_loop(self.new_event_loop())
    
        if self._local._loop is None:
>           raise RuntimeError('There is no current event loop in thread %r.'
                               % threading.current_thread().name)
E           RuntimeError: There is no current event loop in thread 'MainThread'.

/usr/lib64/python3.12/asyncio/events.py:702: RuntimeError
______ ERROR at setup of test_focus_next_and_previous_with_type_selector _______

self = App(title='App', classes={'-dark-mode'}, pseudo_classes={'focus', 'dark'})
screen = Screen(), callback = None, wait_for_dismiss = False

    def push_screen(
        self,
        screen: Screen[ScreenResultType] | str,
        callback: ScreenResultCallbackType[ScreenResultType] | None = None,
        wait_for_dismiss: bool = False,
    ) -> AwaitMount | asyncio.Future[ScreenResultType]:
            raise TypeError(
                f"push_screen requires a Screen instance or str; not {screen!r}"
            )
    
        try:
>           loop = asyncio.get_running_loop()
E           RuntimeError: no running event loop

.run_venv/lib64/python3/site-packages/textual/app.py:2499: RuntimeError

During handling of the above exception, another exception occurred:

    @pytest.fixture
    def screen() -> Screen:
        app = App()
    
        with app._context():
>           app.push_screen(Screen())

tests/test_focus.py:27: 
_ _ _ _ _ _ _ _ _ _ _ _ _ _ _ _ _ _ _ _ _ _ _ _ _ _ _ _ _ _ _ _ _ _ _ _ _ _ _ _ 
_ _ _ _ _ _ _ _ _ _ _ _ _ _ _ _ _ _ _ _ _ _ _ _ _ _ _ _ _ _ _ _ _ _ _ _ _ _ _ _ 
.run_venv/lib64/python3/site-packages/textual/app.py:2502: in push_screen
    future: asyncio.Future[ScreenResultType] = asyncio.Future()
_ _ _ _ _ _ _ _ _ _ _ _ _ _ _ _ _ _ _ _ _ _ _ _ _ _ _ _ _ _ _ _ _ _ _ _ _ _ _ _ 

self = <asyncio.unix_events._UnixDefaultEventLoopPolicy object at 0x7f45f6bb5bb0>

    def get_event_loop(self):
        """Get the event loop for the current context.
    
        Returns an instance of EventLoop or raises an exception.
        """
        if (self._local._loop is None and
                not self._local._set_called and
                threading.current_thread() is threading.main_thread()):
            stacklevel = 2
            try:
                f = sys._getframe(1)
            except AttributeError:
                pass
            else:
            warnings.warn('There is no current event loop',
                          DeprecationWarning, stacklevel=stacklevel)
            self.set_event_loop(self.new_event_loop())
    
        if self._local._loop is None:
>           raise RuntimeError('There is no current event loop in thread %r.'
                               % threading.current_thread().name)
E           RuntimeError: There is no current event loop in thread 'MainThread'.

/usr/lib64/python3.12/asyncio/events.py:702: RuntimeError
_______ ERROR at setup of test_focus_next_and_previous_with_str_selector _______

self = App(title='App', classes={'-dark-mode'}, pseudo_classes={'focus', 'dark'})
screen = Screen(), callback = None, wait_for_dismiss = False

    def push_screen(
        self,
        screen: Screen[ScreenResultType] | str,
        callback: ScreenResultCallbackType[ScreenResultType] | None = None,
        wait_for_dismiss: bool = False,
    ) -> AwaitMount | asyncio.Future[ScreenResultType]:
            raise TypeError(
                f"push_screen requires a Screen instance or str; not {screen!r}"
            )
    
        try:
>           loop = asyncio.get_running_loop()
E           RuntimeError: no running event loop

.run_venv/lib64/python3/site-packages/textual/app.py:2499: RuntimeError

During handling of the above exception, another exception occurred:

    @pytest.fixture
    def screen() -> Screen:
        app = App()
    
        with app._context():
>           app.push_screen(Screen())

tests/test_focus.py:27: 
_ _ _ _ _ _ _ _ _ _ _ _ _ _ _ _ _ _ _ _ _ _ _ _ _ _ _ _ _ _ _ _ _ _ _ _ _ _ _ _ 
_ _ _ _ _ _ _ _ _ _ _ _ _ _ _ _ _ _ _ _ _ _ _ _ _ _ _ _ _ _ _ _ _ _ _ _ _ _ _ _ 
.run_venv/lib64/python3/site-packages/textual/app.py:2502: in push_screen
    future: asyncio.Future[ScreenResultType] = asyncio.Future()
_ _ _ _ _ _ _ _ _ _ _ _ _ _ _ _ _ _ _ _ _ _ _ _ _ _ _ _ _ _ _ _ _ _ _ _ _ _ _ _ 

self = <asyncio.unix_events._UnixDefaultEventLoopPolicy object at 0x7f45f6bb5bb0>

    def get_event_loop(self):
        """Get the event loop for the current context.
    
        Returns an instance of EventLoop or raises an exception.
        """
        if (self._local._loop is None and
                not self._local._set_called and
                threading.current_thread() is threading.main_thread()):
            stacklevel = 2
            try:
                f = sys._getframe(1)
            except AttributeError:
                pass
            else:
            warnings.warn('There is no current event loop',
                          DeprecationWarning, stacklevel=stacklevel)
            self.set_event_loop(self.new_event_loop())
    
        if self._local._loop is None:
>           raise RuntimeError('There is no current event loop in thread %r.'
                               % threading.current_thread().name)
E           RuntimeError: There is no current event loop in thread 'MainThread'.

/usr/lib64/python3.12/asyncio/events.py:702: RuntimeError
_ ERROR at setup of test_focus_next_and_previous_with_str_selector_without_self _

self = App(title='App', classes={'-dark-mode'}, pseudo_classes={'focus', 'dark'})
screen = Screen(), callback = None, wait_for_dismiss = False

    def push_screen(
        self,
        screen: Screen[ScreenResultType] | str,
        callback: ScreenResultCallbackType[ScreenResultType] | None = None,
        wait_for_dismiss: bool = False,
    ) -> AwaitMount | asyncio.Future[ScreenResultType]:
            raise TypeError(
                f"push_screen requires a Screen instance or str; not {screen!r}"
            )
    
        try:
>           loop = asyncio.get_running_loop()
E           RuntimeError: no running event loop

.run_venv/lib64/python3/site-packages/textual/app.py:2499: RuntimeError

During handling of the above exception, another exception occurred:

    @pytest.fixture
    def screen() -> Screen:
        app = App()
    
        with app._context():
>           app.push_screen(Screen())

tests/test_focus.py:27: 
_ _ _ _ _ _ _ _ _ _ _ _ _ _ _ _ _ _ _ _ _ _ _ _ _ _ _ _ _ _ _ _ _ _ _ _ _ _ _ _ 
_ _ _ _ _ _ _ _ _ _ _ _ _ _ _ _ _ _ _ _ _ _ _ _ _ _ _ _ _ _ _ _ _ _ _ _ _ _ _ _ 
.run_venv/lib64/python3/site-packages/textual/app.py:2502: in push_screen
    future: asyncio.Future[ScreenResultType] = asyncio.Future()
_ _ _ _ _ _ _ _ _ _ _ _ _ _ _ _ _ _ _ _ _ _ _ _ _ _ _ _ _ _ _ _ _ _ _ _ _ _ _ _ 

self = <asyncio.unix_events._UnixDefaultEventLoopPolicy object at 0x7f45f6bb5bb0>

    def get_event_loop(self):
        """Get the event loop for the current context.
    
        Returns an instance of EventLoop or raises an exception.
        """
        if (self._local._loop is None and
                not self._local._set_called and
                threading.current_thread() is threading.main_thread()):
            stacklevel = 2
            try:
                f = sys._getframe(1)
            except AttributeError:
                pass
            else:
            raise TypeError(
                f"push_screen requires a Screen instance or str; not {screen!r}"
            )
    
        try:
>           loop = asyncio.get_running_loop()
E           RuntimeError: no running event loop

.run_venv/lib64/python3/site-packages/textual/app.py:2499: RuntimeError

During handling of the above exception, another exception occurred:

    def test_focus_chain():
        app = App()
        with app._context():
>           app.push_screen(Screen())

tests/test_focus.py:48: 
_ _ _ _ _ _ _ _ _ _ _ _ _ _ _ _ _ _ _ _ _ _ _ _ _ _ _ _ _ _ _ _ _ _ _ _ _ _ _ _ 
_ _ _ _ _ _ _ _ _ _ _ _ _ _ _ _ _ _ _ _ _ _ _ _ _ _ _ _ _ _ _ _ _ _ _ _ _ _ _ _ 
.run_venv/lib64/python3/site-packages/textual/app.py:2502: in push_screen
.run_venv/lib64/python3/site-packages/textual/app.py:2502: in push_screen
    future: asyncio.Future[ScreenResultType] = asyncio.Future()
    future: asyncio.Future[ScreenResultType] = asyncio.Future()
_ _ _ _ _ _ _ _ _ _ _ _ _ _ _ _ _ _ _ _ _ _ _ _ _ _ _ _ _ _ _ _ _ _ _ _ _ _ _ _ 

self = <asyncio.unix_events._UnixDefaultEventLoopPolicy object at 0x7f45f6bb5bb0>

    def get_event_loop(self):
        """Get the event loop for the current context.
    
        Returns an instance of EventLoop or raises an exception.
        """
        if (self._local._loop is None and
                not self._local._set_called and
                threading.current_thread() is threading.main_thread()):
            stacklevel = 2
            try:
                f = sys._getframe(1)
            except AttributeError:
                pass
            else:
            raise TypeError(
                f"push_screen requires a Screen instance or str; not {screen!r}"
            )
    
        try:
>           loop = asyncio.get_running_loop()
E           RuntimeError: no running event loop

.run_venv/lib64/python3/site-packages/textual/app.py:2499: RuntimeError

During handling of the above exception, another exception occurred:

    def test_allow_focus():
        """Test allow_focus and allow_focus_children are called and the result used."""
        focusable_allow_focus_called = False
        non_focusable_allow_focus_called = False
    
        class Focusable(Widget, can_focus=False):
            def allow_focus(self) -> bool:
                nonlocal focusable_allow_focus_called
                focusable_allow_focus_called = True
_ _ _ _ _ _ _ _ _ _ _ _ _ _ _ _ _ _ _ _ _ _ _ _ _ _ _ _ _ _ _ _ _ _ _ _ _ _ _ _ 
.run_venv/lib64/python3/site-packages/textual/app.py:2502: in push_screen
    future: asyncio.Future[ScreenResultType] = asyncio.Future()
_ _ _ _ _ _ _ _ _ _ _ _ _ _ _ _ _ _ _ _ _ _ _ _ _ _ _ _ _ _ _ _ _ _ _ _ _ _ _ _ 

self = <asyncio.unix_events._UnixDefaultEventLoopPolicy object at 0x7f45f6bb5bb0>

    def get_event_loop(self):
        """Get the event loop for the current context.
    
        Returns an instance of EventLoop or raises an exception.
        """
        if (self._local._loop is None and
                not self._local._set_called and
                threading.current_thread() is threading.main_thread()):
            stacklevel = 2
            try:
                f = sys._getframe(1)
            except AttributeError:
                pass
            else:
            raise TypeError(
                f"push_screen requires a Screen instance or str; not {screen!r}"
            )
    
        try:
>           loop = asyncio.get_running_loop()
E           RuntimeError: no running event loop

.run_venv/lib64/python3/site-packages/textual/app.py:2499: RuntimeError

During handling of the above exception, another exception occurred:

    def test_focus_next_and_previous_with_type_selector_without_self():
        """Test moving the focus with a selector that does not match the currently focused node."""
        app = App()
        with app._context():
>           app.push_screen(Screen())

tests/test_focus.py:194: 
_ _ _ _ _ _ _ _ _ _ _ _ _ _ _ _ _ _ _ _ _ _ _ _ _ _ _ _ _ _ _ _ _ _ _ _ _ _ _ _ 
_ _ _ _ _ _ _ _ _ _ _ _ _ _ _ _ _ _ _ _ _ _ _ _ _ _ _ _ _ _ _ _ _ _ _ _ _ _ _ _ 
.run_venv/lib64/python3/site-packages/textual/app.py:2502: in push_screen
.run_venv/lib64/python3/site-packages/textual/app.py:2502: in push_screen
    future: asyncio.Future[ScreenResultType] = asyncio.Future()
_ _ _ _ _ _ _ _ _ _ _ _ _ _ _ _ _ _ _ _ _ _ _ _ _ _ _ _ _ _ _ _ _ _ _ _ _ _ _ _ 

self = <asyncio.unix_events._UnixDefaultEventLoopPolicy object at 0x7f45f6bb5bb0>

    def get_event_loop(self):
        """Get the event loop for the current context.
    
        Returns an instance of EventLoop or raises an exception.
        """
        if (self._local._loop is None and
                not self._local._set_called and
                threading.current_thread() is threading.main_thread()):
            stacklevel = 2
            try:
                f = sys._getframe(1)
            except AttributeError:
                pass
            else:
    
        if self._local._loop is None:
>           raise RuntimeError('There is no current event loop in thread %r.'
                               % threading.current_thread().name)
                               % threading.current_thread().name)
E           RuntimeError: There is no current event loop in thread 'MainThread'.
E           RuntimeError: There is no current event loop in thread 'MainThread'.
E           RuntimeError: There is no current event loop in thread 'MainThread'.




/usr/lib64/python3.12/asyncio/events.py:702: RuntimeError
/usr/lib64/python3.12/asyncio/events.py:702: RuntimeError
/usr/lib64/python3.12/asyncio/events.py:702: RuntimeError
/usr/lib64/python3.12/asyncio/events.py:702: RuntimeError
/usr/lib64/python3.12/asyncio/events.py:702: RuntimeError
=========================== short test summary info ============================
=========================== short test summary info ============================
=========================== short test summary info ============================
=========================== short test summary info ============================
=========================== short test summary info ============================
=========================== short test summary info ============================
SKIPPED [1] tests/test_win_sleep.py:14: We only need to test this on Windows.
SKIPPED [1] tests/test_win_sleep.py:14: We only need to test this on Windows.
SKIPPED [1] tests/test_win_sleep.py:14: We only need to test this on Windows.
SKIPPED [1] tests/test_win_sleep.py:14: We only need to test this on Windows.
SKIPPED [1] tests/test_win_sleep.py:14: We only need to test this on Windows.
SKIPPED [1] tests/test_win_sleep.py:14: We only need to test this on Windows.
SKIPPED [1] tests/test_win_sleep.py:14: We only need to test this on Windows.
XFAIL tests/css/test_inheritance.py::test_inheritance - Overlapping styles should prioritize the most recent widget in the inheritance chain
XFAIL tests/css/test_inheritance.py::test_inheritance - Overlapping styles should prioritize the most recent widget in the inheritance chain
XFAIL tests/css/test_inheritance.py::test_inheritance - Overlapping styles should prioritize the most recent widget in the inheritance chain
XFAIL tests/css/test_inheritance.py::test_inheritance - Overlapping styles should prioritize the most recent widget in the inheritance chain
XFAIL tests/css/test_inheritance.py::test_inheritance - Overlapping styles should prioritize the most recent widget in the inheritance chain
XFAIL tests/css/test_inheritance.py::test_inheritance - Overlapping styles should prioritize the most recent widget in the inheritance chain
XFAIL tests/css/test_inheritance.py::test_inheritance - Overlapping styles should prioritize the most recent widget in the inheritance chain
XFAIL tests/css/test_inheritance.py::test_inheritance - Overlapping styles should prioritize the most recent widget in the inheritance chain
XFAIL tests/test_content_switcher.py::test_initial_display_unknown_id - The expected exception doesn't appear to make it to pytest -- perhaps related to https://github.com/Textualize/textual/issues/1972
XFAIL tests/test_content_switcher.py::test_initial_display_unknown_id - The expected exception doesn't appear to make it to pytest -- perhaps related to https://github.com/Textualize/textual/issues/1972
XFAIL tests/test_content_switcher.py::test_initial_display_unknown_id - The expected exception doesn't appear to make it to pytest -- perhaps related to https://github.com/Textualize/textual/issues/1972
XFAIL tests/test_content_switcher.py::test_initial_display_unknown_id - The expected exception doesn't appear to make it to pytest -- perhaps related to https://github.com/Textualize/textual/issues/1972
XFAIL tests/test_content_switcher.py::test_initial_display_unknown_id - The expected exception doesn't appear to make it to pytest -- perhaps related to https://github.com/Textualize/textual/issues/1972
XFAIL tests/test_content_switcher.py::test_initial_display_unknown_id - The expected exception doesn't appear to make it to pytest -- perhaps related to https://github.com/Textualize/textual/issues/1972
XFAIL tests/test_content_switcher.py::test_initial_display_unknown_id - The expected exception doesn't appear to make it to pytest -- perhaps related to https://github.com/Textualize/textual/issues/1972
XFAIL tests/test_content_switcher.py::test_initial_display_unknown_id - The expected exception doesn't appear to make it to pytest -- perhaps related to https://github.com/Textualize/textual/issues/1972
XFAIL tests/test_content_switcher.py::test_initial_display_unknown_id - The expected exception doesn't appear to make it to pytest -- perhaps related to https://github.com/Textualize/textual/issues/1972
XFAIL tests/test_gc.py::test_gc
XFAIL tests/test_gc.py::test_gc
XFAIL tests/test_gc.py::test_gc
XFAIL tests/test_gc.py::test_gc
XFAIL tests/test_gc.py::test_gc
XFAIL tests/test_gc.py::test_gc
XFAIL tests/test_gc.py::test_gc
XFAIL tests/test_gc.py::test_gc
XFAIL tests/test_gc.py::test_gc
XFAIL tests/test_gc.py::test_gc
XFAIL tests/test_xterm_parser.py::test_escape_sequence_resulting_in_multiple_keypresses
XFAIL tests/test_xterm_parser.py::test_escape_sequence_resulting_in_multiple_keypresses
XFAIL tests/test_xterm_parser.py::test_escape_sequence_resulting_in_multiple_keypresses
XFAIL tests/test_xterm_parser.py::test_escape_sequence_resulting_in_multiple_keypresses
XFAIL tests/test_xterm_parser.py::test_escape_sequence_resulting_in_multiple_keypresses
XFAIL tests/test_xterm_parser.py::test_escape_sequence_resulting_in_multiple_keypresses
XFAIL tests/test_xterm_parser.py::test_escape_sequence_resulting_in_multiple_keypresses
XFAIL tests/test_xterm_parser.py::test_escape_sequence_resulting_in_multiple_keypresses
XFAIL tests/test_xterm_parser.py::test_escape_sequence_resulting_in_multiple_keypresses
XFAIL tests/test_xterm_parser.py::test_escape_sequence_resulting_in_multiple_keypresses
XFAIL tests/test_xterm_parser.py::test_escape_sequence_resulting_in_multiple_keypresses
ERROR tests/test_focus.py::test_focus_next_and_previous - RuntimeError: There is no current event loop in thread 'MainThread'.
ERROR tests/test_focus.py::test_focus_next_and_previous - RuntimeError: There is no current event loop in thread 'MainThread'.
ERROR tests/test_focus.py::test_focus_next_and_previous - RuntimeError: There is no current event loop in thread 'MainThread'.
ERROR tests/test_focus.py::test_focus_next_and_previous - RuntimeError: There is no current event loop in thread 'MainThread'.
ERROR tests/test_focus.py::test_focus_next_and_previous - RuntimeError: There is no current event loop in thread 'MainThread'.
ERROR tests/test_focus.py::test_focus_next_and_previous - RuntimeError: There is no current event loop in thread 'MainThread'.
ERROR tests/test_focus.py::test_focus_next_and_previous - RuntimeError: There is no current event loop in thread 'MainThread'.
ERROR tests/test_focus.py::test_focus_next_and_previous - RuntimeError: There is no current event loop in thread 'MainThread'.
ERROR tests/test_focus.py::test_focus_next_and_previous - RuntimeError: There is no current event loop in thread 'MainThread'.
ERROR tests/test_focus.py::test_focus_next_and_previous - RuntimeError: There is no current event loop in thread 'MainThread'.
ERROR tests/test_focus.py::test_focus_next_and_previous - RuntimeError: There is no current event loop in thread 'MainThread'.
ERROR tests/test_focus.py::test_focus_next_and_previous - RuntimeError: There is no current event loop in thread 'MainThread'.
ERROR tests/test_focus.py::test_focus_next_wrap_around - RuntimeError: There is no current event loop in thread 'MainThread'.
ERROR tests/test_focus.py::test_focus_next_wrap_around - RuntimeError: There is no current event loop in thread 'MainThread'.
ERROR tests/test_focus.py::test_focus_next_wrap_around - RuntimeError: There is no current event loop in thread 'MainThread'.
ERROR tests/test_focus.py::test_focus_next_wrap_around - RuntimeError: There is no current event loop in thread 'MainThread'.
ERROR tests/test_focus.py::test_focus_next_wrap_around - RuntimeError: There is no current event loop in thread 'MainThread'.
ERROR tests/test_focus.py::test_focus_next_wrap_around - RuntimeError: There is no current event loop in thread 'MainThread'.
ERROR tests/test_focus.py::test_focus_next_wrap_around - RuntimeError: There is no current event loop in thread 'MainThread'.
ERROR tests/test_focus.py::test_focus_next_wrap_around - RuntimeError: There is no current event loop in thread 'MainThread'.
ERROR tests/test_focus.py::test_focus_next_wrap_around - RuntimeError: There is no current event loop in thread 'MainThread'.
ERROR tests/test_focus.py::test_focus_next_wrap_around - RuntimeError: There is no current event loop in thread 'MainThread'.
ERROR tests/test_focus.py::test_focus_next_wrap_around - RuntimeError: There is no current event loop in thread 'MainThread'.
ERROR tests/test_focus.py::test_focus_next_wrap_around - RuntimeError: There is no current event loop in thread 'MainThread'.
ERROR tests/test_focus.py::test_focus_next_wrap_around - RuntimeError: There is no current event loop in thread 'MainThread'.
ERROR tests/test_focus.py::test_focus_previous_wrap_around - RuntimeError: There is no current event loop in thread 'MainThread'.
ERROR tests/test_focus.py::test_focus_previous_wrap_around - RuntimeError: There is no current event loop in thread 'MainThread'.
ERROR tests/test_focus.py::test_focus_previous_wrap_around - RuntimeError: There is no current event loop in thread 'MainThread'.
ERROR tests/test_focus.py::test_focus_previous_wrap_around - RuntimeError: There is no current event loop in thread 'MainThread'.
ERROR tests/test_focus.py::test_focus_previous_wrap_around - RuntimeError: There is no current event loop in thread 'MainThread'.
ERROR tests/test_focus.py::test_focus_previous_wrap_around - RuntimeError: There is no current event loop in thread 'MainThread'.
ERROR tests/test_focus.py::test_focus_previous_wrap_around - RuntimeError: There is no current event loop in thread 'MainThread'.
ERROR tests/test_focus.py::test_focus_previous_wrap_around - RuntimeError: There is no current event loop in thread 'MainThread'.
ERROR tests/test_focus.py::test_focus_previous_wrap_around - RuntimeError: There is no current event loop in thread 'MainThread'.
ERROR tests/test_focus.py::test_focus_previous_wrap_around - RuntimeError: There is no current event loop in thread 'MainThread'.
ERROR tests/test_focus.py::test_focus_previous_wrap_around - RuntimeError: There is no current event loop in thread 'MainThread'.
ERROR tests/test_focus.py::test_focus_previous_wrap_around - RuntimeError: There is no current event loop in thread 'MainThread'.
ERROR tests/test_focus.py::test_focus_previous_wrap_around - RuntimeError: There is no current event loop in thread 'MainThread'.
ERROR tests/test_focus.py::test_wrap_around_selector - RuntimeError: There is no current event loop in thread 'MainThread'.
ERROR tests/test_focus.py::test_wrap_around_selector - RuntimeError: There is no current event loop in thread 'MainThread'.
ERROR tests/test_focus.py::test_wrap_around_selector - RuntimeError: There is no current event loop in thread 'MainThread'.
ERROR tests/test_focus.py::test_wrap_around_selector - RuntimeError: There is no current event loop in thread 'MainThread'.
ERROR tests/test_focus.py::test_wrap_around_selector - RuntimeError: There is no current event loop in thread 'MainThread'.
ERROR tests/test_focus.py::test_wrap_around_selector - RuntimeError: There is no current event loop in thread 'MainThread'.
ERROR tests/test_focus.py::test_wrap_around_selector - RuntimeError: There is no current event loop in thread 'MainThread'.
ERROR tests/test_focus.py::test_wrap_around_selector - RuntimeError: There is no current event loop in thread 'MainThread'.
ERROR tests/test_focus.py::test_wrap_around_selector - RuntimeError: There is no current event loop in thread 'MainThread'.
ERROR tests/test_focus.py::test_wrap_around_selector - RuntimeError: There is no current event loop in thread 'MainThread'.
ERROR tests/test_focus.py::test_wrap_around_selector - RuntimeError: There is no current event loop in thread 'MainThread'.
ERROR tests/test_focus.py::test_wrap_around_selector - RuntimeError: There is no current event loop in thread 'MainThread'.
ERROR tests/test_focus.py::test_wrap_around_selector - RuntimeError: There is no current event loop in thread 'MainThread'.
ERROR tests/test_focus.py::test_wrap_around_selector - RuntimeError: There is no current event loop in thread 'MainThread'.
ERROR tests/test_focus.py::test_no_focus_empty_selector - RuntimeError: There is no current event loop in thread 'MainThread'.
ERROR tests/test_focus.py::test_no_focus_empty_selector - RuntimeError: There is no current event loop in thread 'MainThread'.
ERROR tests/test_focus.py::test_no_focus_empty_selector - RuntimeError: There is no current event loop in thread 'MainThread'.
ERROR tests/test_focus.py::test_no_focus_empty_selector - RuntimeError: There is no current event loop in thread 'MainThread'.
ERROR tests/test_focus.py::test_no_focus_empty_selector - RuntimeError: There is no current event loop in thread 'MainThread'.
ERROR tests/test_focus.py::test_no_focus_empty_selector - RuntimeError: There is no current event loop in thread 'MainThread'.
ERROR tests/test_focus.py::test_no_focus_empty_selector - RuntimeError: There is no current event loop in thread 'MainThread'.
ERROR tests/test_focus.py::test_no_focus_empty_selector - RuntimeError: There is no current event loop in thread 'MainThread'.
ERROR tests/test_focus.py::test_no_focus_empty_selector - RuntimeError: There is no current event loop in thread 'MainThread'.
ERROR tests/test_focus.py::test_no_focus_empty_selector - RuntimeError: There is no current event loop in thread 'MainThread'.
ERROR tests/test_focus.py::test_no_focus_empty_selector - RuntimeError: There is no current event loop in thread 'MainThread'.
ERROR tests/test_focus.py::test_no_focus_empty_selector - RuntimeError: There is no current event loop in thread 'MainThread'.
ERROR tests/test_focus.py::test_no_focus_empty_selector - RuntimeError: There is no current event loop in thread 'MainThread'.
ERROR tests/test_focus.py::test_no_focus_empty_selector - RuntimeError: There is no current event loop in thread 'MainThread'.
ERROR tests/test_focus.py::test_no_focus_empty_selector - RuntimeError: There is no current event loop in thread 'MainThread'.
ERROR tests/test_focus.py::test_focus_next_and_previous_with_type_selector - RuntimeError: There is no current event loop in thread 'MainThread'.
ERROR tests/test_focus.py::test_focus_next_and_previous_with_type_selector - RuntimeError: There is no current event loop in thread 'MainThread'.
ERROR tests/test_focus.py::test_focus_next_and_previous_with_type_selector - RuntimeError: There is no current event loop in thread 'MainThread'.
ERROR tests/test_focus.py::test_focus_next_and_previous_with_type_selector - RuntimeError: There is no current event loop in thread 'MainThread'.
ERROR tests/test_focus.py::test_focus_next_and_previous_with_type_selector - RuntimeError: There is no current event loop in thread 'MainThread'.
ERROR tests/test_focus.py::test_focus_next_and_previous_with_type_selector - RuntimeError: There is no current event loop in thread 'MainThread'.
ERROR tests/test_focus.py::test_focus_next_and_previous_with_type_selector - RuntimeError: There is no current event loop in thread 'MainThread'.
ERROR tests/test_focus.py::test_focus_next_and_previous_with_type_selector - RuntimeError: There is no current event loop in thread 'MainThread'.
ERROR tests/test_focus.py::test_focus_next_and_previous_with_type_selector - RuntimeError: There is no current event loop in thread 'MainThread'.
ERROR tests/test_focus.py::test_focus_next_and_previous_with_type_selector - RuntimeError: There is no current event loop in thread 'MainThread'.
ERROR tests/test_focus.py::test_focus_next_and_previous_with_type_selector - RuntimeError: There is no current event loop in thread 'MainThread'.
ERROR tests/test_focus.py::test_focus_next_and_previous_with_type_selector - RuntimeError: There is no current event loop in thread 'MainThread'.
ERROR tests/test_focus.py::test_focus_next_and_previous_with_type_selector - RuntimeError: There is no current event loop in thread 'MainThread'.
ERROR tests/test_focus.py::test_focus_next_and_previous_with_type_selector - RuntimeError: There is no current event loop in thread 'MainThread'.
ERROR tests/test_focus.py::test_focus_next_and_previous_with_type_selector - RuntimeError: There is no current event loop in thread 'MainThread'.
ERROR tests/test_focus.py::test_focus_next_and_previous_with_str_selector - RuntimeError: There is no current event loop in thread 'MainThread'.
ERROR tests/test_focus.py::test_focus_next_and_previous_with_str_selector - RuntimeError: There is no current event loop in thread 'MainThread'.
ERROR tests/test_focus.py::test_focus_next_and_previous_with_str_selector - RuntimeError: There is no current event loop in thread 'MainThread'.
ERROR tests/test_focus.py::test_focus_next_and_previous_with_str_selector - RuntimeError: There is no current event loop in thread 'MainThread'.
ERROR tests/test_focus.py::test_focus_next_and_previous_with_str_selector - RuntimeError: There is no current event loop in thread 'MainThread'.
ERROR tests/test_focus.py::test_focus_next_and_previous_with_str_selector - RuntimeError: There is no current event loop in thread 'MainThread'.
ERROR tests/test_focus.py::test_focus_next_and_previous_with_str_selector - RuntimeError: There is no current event loop in thread 'MainThread'.
ERROR tests/test_focus.py::test_focus_next_and_previous_with_str_selector - RuntimeError: There is no current event loop in thread 'MainThread'.
ERROR tests/test_focus.py::test_focus_next_and_previous_with_str_selector - RuntimeError: There is no current event loop in thread 'MainThread'.
ERROR tests/test_focus.py::test_focus_next_and_previous_with_str_selector - RuntimeError: There is no current event loop in thread 'MainThread'.
ERROR tests/test_focus.py::test_focus_next_and_previous_with_str_selector - RuntimeError: There is no current event loop in thread 'MainThread'.
ERROR tests/test_focus.py::test_focus_next_and_previous_with_str_selector - RuntimeError: There is no current event loop in thread 'MainThread'.
ERROR tests/test_focus.py::test_focus_next_and_previous_with_str_selector - RuntimeError: There is no current event loop in thread 'MainThread'.
ERROR tests/test_focus.py::test_focus_next_and_previous_with_str_selector - RuntimeError: There is no current event loop in thread 'MainThread'.
ERROR tests/test_focus.py::test_focus_next_and_previous_with_str_selector - RuntimeError: There is no current event loop in thread 'MainThread'.
ERROR tests/test_focus.py::test_focus_next_and_previous_with_str_selector_without_self - RuntimeError: There is no current event loop in thread 'MainThread'.
ERROR tests/test_focus.py::test_focus_next_and_previous_with_str_selector_without_self - RuntimeError: There is no current event loop in thread 'MainThread'.
ERROR tests/test_focus.py::test_focus_next_and_previous_with_str_selector_without_self - RuntimeError: There is no current event loop in thread 'MainThread'.
ERROR tests/test_focus.py::test_focus_next_and_previous_with_str_selector_without_self - RuntimeError: There is no current event loop in thread 'MainThread'.
ERROR tests/test_focus.py::test_focus_next_and_previous_with_str_selector_without_self - RuntimeError: There is no current event loop in thread 'MainThread'.
ERROR tests/test_focus.py::test_focus_next_and_previous_with_str_selector_without_self - RuntimeError: There is no current event loop in thread 'MainThread'.
ERROR tests/test_focus.py::test_focus_next_and_previous_with_str_selector_without_self - RuntimeError: There is no current event loop in thread 'MainThread'.
ERROR tests/test_focus.py::test_focus_next_and_previous_with_str_selector_without_self - RuntimeError: There is no current event loop in thread 'MainThread'.
ERROR tests/test_focus.py::test_focus_next_and_previous_with_str_selector_without_self - RuntimeError: There is no current event loop in thread 'MainThread'.
ERROR tests/test_focus.py::test_focus_next_and_previous_with_str_selector_without_self - RuntimeError: There is no current event loop in thread 'MainThread'.
ERROR tests/test_focus.py::test_focus_next_and_previous_with_str_selector_without_self - RuntimeError: There is no current event loop in thread 'MainThread'.
ERROR tests/test_focus.py::test_focus_next_and_previous_with_str_selector_without_self - RuntimeError: There is no current event loop in thread 'MainThread'.
ERROR tests/test_focus.py::test_focus_next_and_previous_with_str_selector_without_self - RuntimeError: There is no current event loop in thread 'MainThread'.
ERROR tests/test_focus.py::test_focus_next_and_previous_with_str_selector_without_self - RuntimeError: There is no current event loop in thread 'MainThread'.
ERROR tests/test_focus.py::test_focus_next_and_previous_with_str_selector_without_self - RuntimeError: There is no current event loop in thread 'MainThread'.
FAILED tests/test_focus.py::test_focus_chain - RuntimeError: There is no current event loop in thread 'MainThread'.
FAILED tests/test_focus.py::test_focus_chain - RuntimeError: There is no current event loop in thread 'MainThread'.
FAILED tests/test_focus.py::test_focus_chain - RuntimeError: There is no current event loop in thread 'MainThread'.
FAILED tests/test_focus.py::test_focus_chain - RuntimeError: There is no current event loop in thread 'MainThread'.
FAILED tests/test_focus.py::test_focus_chain - RuntimeError: There is no current event loop in thread 'MainThread'.
FAILED tests/test_focus.py::test_focus_chain - RuntimeError: There is no current event loop in thread 'MainThread'.
FAILED tests/test_focus.py::test_focus_chain - RuntimeError: There is no current event loop in thread 'MainThread'.
FAILED tests/test_focus.py::test_focus_chain - RuntimeError: There is no current event loop in thread 'MainThread'.
FAILED tests/test_focus.py::test_focus_chain - RuntimeError: There is no current event loop in thread 'MainThread'.
FAILED tests/test_focus.py::test_focus_chain - RuntimeError: There is no current event loop in thread 'MainThread'.
FAILED tests/test_focus.py::test_focus_chain - RuntimeError: There is no current event loop in thread 'MainThread'.
FAILED tests/test_focus.py::test_focus_chain - RuntimeError: There is no current event loop in thread 'MainThread'.
FAILED tests/test_focus.py::test_focus_chain - RuntimeError: There is no current event loop in thread 'MainThread'.
FAILED tests/test_focus.py::test_focus_chain - RuntimeError: There is no current event loop in thread 'MainThread'.
FAILED tests/test_focus.py::test_allow_focus - RuntimeError: There is no current event loop in thread 'MainThread'.
FAILED tests/test_focus.py::test_allow_focus - RuntimeError: There is no current event loop in thread 'MainThread'.
FAILED tests/test_focus.py::test_allow_focus - RuntimeError: There is no current event loop in thread 'MainThread'.
FAILED tests/test_focus.py::test_allow_focus - RuntimeError: There is no current event loop in thread 'MainThread'.
FAILED tests/test_focus.py::test_allow_focus - RuntimeError: There is no current event loop in thread 'MainThread'.
FAILED tests/test_focus.py::test_allow_focus - RuntimeError: There is no current event loop in thread 'MainThread'.
FAILED tests/test_focus.py::test_allow_focus - RuntimeError: There is no current event loop in thread 'MainThread'.
FAILED tests/test_focus.py::test_allow_focus - RuntimeError: There is no current event loop in thread 'MainThread'.
FAILED tests/test_focus.py::test_allow_focus - RuntimeError: There is no current event loop in thread 'MainThread'.
FAILED tests/test_focus.py::test_allow_focus - RuntimeError: There is no current event loop in thread 'MainThread'.
FAILED tests/test_focus.py::test_allow_focus - RuntimeError: There is no current event loop in thread 'MainThread'.
FAILED tests/test_focus.py::test_allow_focus - RuntimeError: There is no current event loop in thread 'MainThread'.
FAILED tests/test_focus.py::test_allow_focus - RuntimeError: There is no current event loop in thread 'MainThread'.
FAILED tests/test_focus.py::test_allow_focus - RuntimeError: There is no current event loop in thread 'MainThread'.
FAILED tests/test_focus.py::test_focus_next_and_previous_with_type_selector_without_self - RuntimeError: There is no current event loop in thread 'MainThread'.
FAILED tests/test_focus.py::test_focus_next_and_previous_with_type_selector_without_self - RuntimeError: There is no current event loop in thread 'MainThread'.
FAILED tests/test_focus.py::test_focus_next_and_previous_with_type_selector_without_self - RuntimeError: There is no current event loop in thread 'MainThread'.
FAILED tests/test_focus.py::test_focus_next_and_previous_with_type_selector_without_self - RuntimeError: There is no current event loop in thread 'MainThread'.
FAILED tests/test_focus.py::test_focus_next_and_previous_with_type_selector_without_self - RuntimeError: There is no current event loop in thread 'MainThread'.
FAILED tests/test_focus.py::test_focus_next_and_previous_with_type_selector_without_self - RuntimeError: There is no current event loop in thread 'MainThread'.
FAILED tests/test_focus.py::test_focus_next_and_previous_with_type_selector_without_self - RuntimeError: There is no current event loop in thread 'MainThread'.
FAILED tests/test_focus.py::test_focus_next_and_previous_with_type_selector_without_self - RuntimeError: There is no current event loop in thread 'MainThread'.
FAILED tests/test_focus.py::test_focus_next_and_previous_with_type_selector_without_self - RuntimeError: There is no current event loop in thread 'MainThread'.
FAILED tests/test_focus.py::test_focus_next_and_previous_with_type_selector_without_self - RuntimeError: There is no current event loop in thread 'MainThread'.
FAILED tests/test_focus.py::test_focus_next_and_previous_with_type_selector_without_self - RuntimeError: There is no current event loop in thread 'MainThread'.
FAILED tests/test_focus.py::test_focus_next_and_previous_with_type_selector_without_self - RuntimeError: There is no current event loop in thread 'MainThread'.
FAILED tests/test_focus.py::test_focus_next_and_previous_with_type_selector_without_self - RuntimeError: There is no current event loop in thread 'MainThread'.
FAILED tests/test_focus.py::test_focus_next_and_previous_with_type_selector_without_self - RuntimeError: There is no current event loop in thread 'MainThread'.
= 3 failed, 2657 passed, 1 skipped, 4 deselected, 4 xfailed, 8 errors in 165.21s (0:02:45) =
= 3 failed, 2657 passed, 1 skipped, 4 deselected, 4 xfailed, 8 errors in 165.21s (0:02:45) =
= 3 failed, 2657 passed, 1 skipped, 4 deselected, 4 xfailed, 8 errors in 165.21s (0:02:45) =
= 3 failed, 2657 passed, 1 skipped, 4 deselected, 4 xfailed, 8 errors in 165.21s (0:02:45) =
= 3 failed, 2657 passed, 1 skipped, 4 deselected, 4 xfailed, 8 errors in 165.21s (0:02:45) =
= 3 failed, 2657 passed, 1 skipped, 4 deselected, 4 xfailed, 8 errors in 165.21s (0:02:45) =
= 3 failed, 2657 passed, 1 skipped, 4 deselected, 4 xfailed, 8 errors in 165.21s (0:02:45) =
= 3 failed, 2657 passed, 1 skipped, 4 deselected, 4 xfailed, 8 errors in 165.21s (0:02:45) =
= 3 failed, 2657 passed, 1 skipped, 4 deselected, 4 xfailed, 8 errors in 165.21s (0:02:45) =
= 3 failed, 2657 passed, 1 skipped, 4 deselected, 4 xfailed, 8 errors in 165.21s (0:02:45) =
= 3 failed, 2657 passed, 1 skipped, 4 deselected, 4 xfailed, 8 errors in 165.21s (0:02:45) =
= 3 failed, 2657 passed, 1 skipped, 4 deselected, 4 xfailed, 8 errors in 165.21s (0:02:45) =
= 3 failed, 2657 passed, 1 skipped, 4 deselected, 4 xfailed, 8 errors in 165.21s (0:02:45) =
INFO     : Command's result: FAILURE
INFO     : Command's result: FAILURE
INFO     : Command's result: FAILURE
INFO     : Command's result: FAILURE
INFO     : Command's result: FAILURE
INFO     : Command's result: FAILURE
INFO     : Command's result: FAILURE
INFO     : Command's result: FAILURE
INFO     : Command's result: FAILURE
INFO     : Command's result: FAILURE
INFO     : Command's result: FAILURE
INFO     : Command's result: FAILURE
INFO     : Command's result: FAILURE
INFO     : Command's error: Command '['python3', '-m', 'pytest', '-ra', '-Wignore', '-ra', 'tests', '-k', '    not test_textual_env_var and     not test_register_language and     not test_register_language_existing_language and     not test_language_binary_missing', '--ignore=tests/snapshot_tests/test_snapshots.py', '--ignore=tests/input/test_input_value_visibility.py']' returned non-zero exit status 1.
INFO     : Command's error: Command '['python3', '-m', 'pytest', '-ra', '-Wignore', '-ra', 'tests', '-k', '    not test_textual_env_var and     not test_register_language and     not test_register_language_existing_language and     not test_language_binary_missing', '--ignore=tests/snapshot_tests/test_snapshots.py', '--ignore=tests/input/test_input_value_visibility.py']' returned non-zero exit status 1.
INFO     : Command's error: Command '['python3', '-m', 'pytest', '-ra', '-Wignore', '-ra', 'tests', '-k', '    not test_textual_env_var and     not test_register_language and     not test_register_language_existing_language and     not test_language_binary_missing', '--ignore=tests/snapshot_tests/test_snapshots.py', '--ignore=tests/input/test_input_value_visibility.py']' returned non-zero exit status 1.
INFO     : Command's error: Command '['python3', '-m', 'pytest', '-ra', '-Wignore', '-ra', 'tests', '-k', '    not test_textual_env_var and     not test_register_language and     not test_register_language_existing_language and     not test_language_binary_missing', '--ignore=tests/snapshot_tests/test_snapshots.py', '--ignore=tests/input/test_input_value_visibility.py']' returned non-zero exit status 1.
INFO     : Command's error: Command '['python3', '-m', 'pytest', '-ra', '-Wignore', '-ra', 'tests', '-k', '    not test_textual_env_var and     not test_register_language and     not test_register_language_existing_language and     not test_language_binary_missing', '--ignore=tests/snapshot_tests/test_snapshots.py', '--ignore=tests/input/test_input_value_visibility.py']' returned non-zero exit status 1.
INFO     : Command's error: Command '['python3', '-m', 'pytest', '-ra', '-Wignore', '-ra', 'tests', '-k', '    not test_textual_env_var and     not test_register_language and     not test_register_language_existing_language and     not test_language_binary_missing', '--ignore=tests/snapshot_tests/test_snapshots.py', '--ignore=tests/input/test_input_value_visibility.py']' returned non-zero exit status 1.
INFO     : Command's error: Command '['python3', '-m', 'pytest', '-ra', '-Wignore', '-ra', 'tests', '-k', '    not test_textual_env_var and     not test_register_language and     not test_register_language_existing_language and     not test_language_binary_missing', '--ignore=tests/snapshot_tests/test_snapshots.py', '--ignore=tests/input/test_input_value_visibility.py']' returned non-zero exit status 1.
INFO     : Command's error: Command '['python3', '-m', 'pytest', '-ra', '-Wignore', '-ra', 'tests', '-k', '    not test_textual_env_var and     not test_register_language and     not test_register_language_existing_language and     not test_language_binary_missing', '--ignore=tests/snapshot_tests/test_snapshots.py', '--ignore=tests/input/test_input_value_visibility.py']' returned non-zero exit status 1.
INFO     : Command's error: Command '['python3', '-m', 'pytest', '-ra', '-Wignore', '-ra', 'tests', '-k', '    not test_textual_env_var and     not test_register_language and     not test_register_language_existing_language and     not test_language_binary_missing', '--ignore=tests/snapshot_tests/test_snapshots.py', '--ignore=tests/input/test_input_value_visibility.py']' returned non-zero exit status 1.
INFO     : Command's error: Command '['python3', '-m', 'pytest', '-ra', '-Wignore', '-ra', 'tests', '-k', '    not test_textual_env_var and     not test_register_language and     not test_register_language_existing_language and     not test_language_binary_missing', '--ignore=tests/snapshot_tests/test_snapshots.py', '--ignore=tests/input/test_input_value_visibility.py']' returned non-zero exit status 1.
INFO     : Command's error: Command '['python3', '-m', 'pytest', '-ra', '-Wignore', '-ra', 'tests', '-k', '    not test_textual_env_var and     not test_register_language and     not test_register_language_existing_language and     not test_language_binary_missing', '--ignore=tests/snapshot_tests/test_snapshots.py', '--ignore=tests/input/test_input_value_visibility.py']' returned non-zero exit status 1.
INFO     : Command's error: Command '['python3', '-m', 'pytest', '-ra', '-Wignore', '-ra', 'tests', '-k', '    not test_textual_env_var and     not test_register_language and     not test_register_language_existing_language and     not test_language_binary_missing', '--ignore=tests/snapshot_tests/test_snapshots.py', '--ignore=tests/input/test_input_value_visibility.py']' returned non-zero exit status 1.
error: Bad exit status from /usr/src/tmp/rpm-tmp.34227 (%check)
error: Bad exit status from /usr/src/tmp/rpm-tmp.34227 (%check)
error: Bad exit status from /usr/src/tmp/rpm-tmp.34227 (%check)
error: Bad exit status from /usr/src/tmp/rpm-tmp.34227 (%check)
error: Bad exit status from /usr/src/tmp/rpm-tmp.34227 (%check)
error: Bad exit status from /usr/src/tmp/rpm-tmp.34227 (%check)
error: Bad exit status from /usr/src/tmp/rpm-tmp.34227 (%check)
error: Bad exit status from /usr/src/tmp/rpm-tmp.34227 (%check)
error: Bad exit status from /usr/src/tmp/rpm-tmp.34227 (%check)
error: Bad exit status from /usr/src/tmp/rpm-tmp.34227 (%check)
error: Bad exit status from /usr/src/tmp/rpm-tmp.34227 (%check)



















RPM build errors:
RPM build errors:
RPM build errors:
RPM build errors:
RPM build errors:
RPM build errors:
RPM build errors:
RPM build errors:
    Bad exit status from /usr/src/tmp/rpm-tmp.34227 (%check)
    Bad exit status from /usr/src/tmp/rpm-tmp.34227 (%check)
    Bad exit status from /usr/src/tmp/rpm-tmp.34227 (%check)
    Bad exit status from /usr/src/tmp/rpm-tmp.34227 (%check)
    Bad exit status from /usr/src/tmp/rpm-tmp.34227 (%check)
    Bad exit status from /usr/src/tmp/rpm-tmp.34227 (%check)
    Bad exit status from /usr/src/tmp/rpm-tmp.34227 (%check)
Command exited with non-zero status 1
Command exited with non-zero status 1
Command exited with non-zero status 1
Command exited with non-zero status 1
Command exited with non-zero status 1
Command exited with non-zero status 1
66.05user 3.83system 2:52.94elapsed 40%CPU (0avgtext+0avgdata 102472maxresident)k
66.05user 3.83system 2:52.94elapsed 40%CPU (0avgtext+0avgdata 102472maxresident)k
66.05user 3.83system 2:52.94elapsed 40%CPU (0avgtext+0avgdata 102472maxresident)k
66.05user 3.83system 2:52.94elapsed 40%CPU (0avgtext+0avgdata 102472maxresident)k
66.05user 3.83system 2:52.94elapsed 40%CPU (0avgtext+0avgdata 102472maxresident)k
0inputs+0outputs (0major+299242minor)pagefaults 0swaps
0inputs+0outputs (0major+299242minor)pagefaults 0swaps
0inputs+0outputs (0major+299242minor)pagefaults 0swaps
0inputs+0outputs (0major+299242minor)pagefaults 0swaps
hsh-rebuild: rebuild of `python3-module-textual-0.85.2-alt1.src.rpm' failed.
hsh-rebuild: rebuild of `python3-module-textual-0.85.2-alt1.src.rpm' failed.
hsh-rebuild: rebuild of `python3-module-textual-0.85.2-alt1.src.rpm' failed.
Command exited with non-zero status 1
Command exited with non-zero status 1
Command exited with non-zero status 1
4.67user 3.37system 3:08.05elapsed 4%CPU (0avgtext+0avgdata 142076maxresident)k
4.67user 3.37system 3:08.05elapsed 4%CPU (0avgtext+0avgdata 142076maxresident)k
280inputs+0outputs (0major+362821minor)pagefaults 0swaps
